Workbook

Sheet 40C
A1: GENSPP | B1: ID_Code | C1: Species | D1: Treat | E1: Sample_no | F1: Date_Time | G1: Weight
A2: ERIMON | B2: {=IF(ISBLANK(A2),"",IF(A2="PROREP (L)",VLOOKUP(LEFT($A2,6),'Data Feed (40C)'!$A$1:$G$10,2,FALSE),IF(A2="PROREP (S)", INDEX('Data Feed (40C)'!B:B, MATCH(LEFT($A2,6), 'Data Feed (40C)'!$A$1:$A$10, 0) + 1), VLOOKUP($A2,'Data Feed (40C)'!$A$1:$G$10,2,FALSE))))} -> JKS240702ERIMON_40C_sample_1 | C2: {=IF(ISBLANK(A2),"",IF(A2="PROREP (L)",VLOOKUP(LEFT($A2,6),'Data Feed (40C)'!$A$1:$G$10,3,FALSE),IF(A2="PROREP (S)", INDEX('Data Feed (40C)'!C:C, MATCH(LEFT($A2,6), 'Data Feed (40C)'!$A$1:$A$10, 0) + 1, +1), VLOOKUP($A2,'Data Feed (40C)'!$A$1:$G$10,3,FALSE))))} -> Erica monsoniana | D2: {=IF(ISBLANK(A2),"",IF(A2="PROREP (L)",VLOOKUP(LEFT($A2,6),'Data Feed (40C)'!$A$1:$G$10,4,FALSE),IF(A2="PROREP (S)", INDEX('Data Feed (40C)'!D:D, MATCH(LEFT($A2,6), 'Data Feed (40C)'!$A$1:$A$10, 0) + 1, +1), VLOOKUP($A2,'Data Feed (40C)'!$A$1:$G$10,4,FALSE))))} -> 40C | E2: {=IF(ISBLANK(A2),"",IF(A2="PROREP (L)",VLOOKUP(LEFT($A2,6),'Data Feed (40C)'!$A$1:$G$10,7,FALSE),IF(A2="PROREP (S)", INDEX('Data Feed (40C)'!G:G, MATCH(LEFT($A2,6), 'Data Feed (40C)'!$A$1:$A$10, 0) + 1, +1), VLOOKUP($A2,'Data Feed (40C)'!$A$1:$G$10,7,FALSE))))} -> 1 | F2: 45477.521 | G2: 1.84
A3: =A2 -> ERIMON | B3: =IF(ISBLANK(A2),"",LEFT(B2,27)&VALUE(RIGHT(B2,1)+1)) -> JKS240702ERIMON_40C_sample_2 | C3: =C2 -> Erica monsoniana | D3: =D2 -> 40C | E3: =IF(ISBLANK(A2),"",E2+1) -> 2 | F3: =F2 -> 45477.521 | G3: 1.695
A4: =A3 -> ERIMON | B4: =IF(ISBLANK(A2),"",LEFT(B3,27)&VALUE(RIGHT(B3,1)+1)) -> JKS240702ERIMON_40C_sample_3 | C4: =C3 -> Erica monsoniana | D4: =D3 -> 40C | E4: =IF(ISBLANK(A2),"",E3+1) -> 3 | F4: =F3 -> 45477.521 | G4: 1.5
A5: =A4 -> ERIMON | B5: =IF(ISBLANK(A2),"",LEFT(B4,27)&VALUE(RIGHT(B4,1)+1)) -> JKS240702ERIMON_40C_sample_4 | C5: =C4 -> Erica monsoniana | D5: =D4 -> 40C | E5: =IF(ISBLANK(A2),"",E4+1) -> 4 | F5: =F4 -> 45477.521 | G5: 3.358
A6: =A5 -> ERIMON | B6: =IF(ISBLANK(A2),"",LEFT(B5,27)&VALUE(RIGHT(B5,1)+1)) -> JKS240702ERIMON_40C_sample_5 | C6: =C5 -> Erica monsoniana | D6: =D5 -> 40C | E6: =IF(ISBLANK(A2),"",E5+1) -> 5 | F6: =F5 -> 45477.521 | G6: 1.177
A7: =A6 -> ERIMON | B7: =IF(ISBLANK(A2),"",LEFT(B6,27)&VALUE(RIGHT(B6,1)+1)) -> JKS240702ERIMON_40C_sample_6 | C7: =C6 -> Erica monsoniana | D7: =D6 -> 40C | E7: =IF(ISBLANK(A2),"",E6+1) -> 6 | F7: =F6 -> 45477.521 | G7: 2.264
A8: PROREP (L) | B8: {=IF(ISBLANK(A8),"",IF(A8="PROREP (L)",VLOOKUP(LEFT($A8,6),'Data Feed (40C)'!$A$1:$G$10,2,FALSE),IF(A8="PROREP (S)", INDEX('Data Feed (40C)'!B:B, MATCH(LEFT($A8,6), 'Data Feed (40C)'!$A$1:$A$10, 0) + 1), VLOOKUP($A8,'Data Feed (40C)'!$A$1:$G$10,2,FALSE))))} -> JKL240702PROREP_40C_sample_1 | C8: {=IF(ISBLANK(A8),"",IF(A8="PROREP (L)",VLOOKUP(LEFT($A8,6),'Data Feed (40C)'!$A$1:$G$10,3,FALSE),IF(A8="PROREP (S)", INDEX('Data Feed (40C)'!C:C, MATCH(LEFT($A8,6), 'Data Feed (40C)'!$A$1:$A$10, 0) + 1, +1), VLOOKUP($A8,'Data Feed (40C)'!$A$1:$G$10,3,FALSE))))} -> Protea repens | D8: {=IF(ISBLANK(A8),"",IF(A8="PROREP (L)",VLOOKUP(LEFT($A8,6),'Data Feed (40C)'!$A$1:$G$10,4,FALSE),IF(A8="PROREP (S)", INDEX('Data Feed (40C)'!D:D, MATCH(LEFT($A8,6), 'Data Feed (40C)'!$A$1:$A$10, 0) + 1, +1), VLOOKUP($A8,'Data Feed (40C)'!$A$1:$G$10,4,FALSE))))} -> 40C | E8: {=IF(ISBLANK(A8),"",IF(A8="PROREP (L)",VLOOKUP(LEFT($A8,6),'Data Feed (40C)'!$A$1:$G$10,7,FALSE),IF(A8="PROREP (S)", INDEX('Data Feed (40C)'!G:G, MATCH(LEFT($A8,6), 'Data Feed (40C)'!$A$1:$A$10, 0) + 1, +1), VLOOKUP($A8,'Data Feed (40C)'!$A$1:$G$10,7,FALSE))))} -> 1 | F8: 45477.572 | G8: 0.575
A9: =A8 -> PROREP (L) | B9: =IF(ISBLANK(A8),"",LEFT(B8,27)&VALUE(RIGHT(B8,1)+1)) -> JKL240702PROREP_40C_sample_2 | C9: =C8 -> Protea repens | D9: =D8 -> 40C | E9: =IF(ISBLANK(A8),"",E8+1) -> 2 | F9: =F8 -> 45477.572 | G9: 0.535
A10: =A9 -> PROREP (L) | B10: =IF(ISBLANK(A8),"",LEFT(B9,27)&VALUE(RIGHT(B9,1)+1)) -> JKL240702PROREP_40C_sample_3 | C10: =C9 -> Protea repens | D10: =D9 -> 40C | E10: =IF(ISBLANK(A8),"",E9+1) -> 3 | F10: =F9 -> 45477.572 | G10: 0.624
A11: =A10 -> PROREP (L) | B11: =IF(ISBLANK(A8),"",LEFT(B10,27)&VALUE(RIGHT(B10,1)+1)) -> JKL240702PROREP_40C_sample_4 | C11: =C10 -> Protea repens | D11: =D10 -> 40C | E11: =IF(ISBLANK(A8),"",E10+1) -> 4 | F11: =F10 -> 45477.572 | G11: 0.296
A12: =A11 -> PROREP (L) | B12: =IF(ISBLANK(A8),"",LEFT(B11,27)&VALUE(RIGHT(B11,1)+1)) -> JKL240702PROREP_40C_sample_5 | C12: =C11 -> Protea repens | D12: =D11 -> 40C | E12: =IF(ISBLANK(A8),"",E11+1) -> 5 | F12: =F11 -> 45477.572 | G12: 0.37
A13: =A12 -> PROREP (L) | B13: =IF(ISBLANK(A8),"",LEFT(B12,27)&VALUE(RIGHT(B12,1)+1)) -> JKL240702PROREP_40C_sample_6 | C13: =C12 -> Protea repens | D13: =D12 -> 40C | E13: =IF(ISBLANK(A8),"",E12+1) -> 6 | F13: =F12 -> 45477.572 | G13: 0.486
A14: ERIMON | B14: {=IF(ISBLANK(A14),"",IF(A14="PROREP (L)",VLOOKUP(LEFT($A14,6),'Data Feed (40C)'!$A$1:$G$10,2,FALSE),IF(A14="PROREP (S)", INDEX('Data Feed (40C)'!B:B, MATCH(LEFT($A14,6), 'Data Feed (40C)'!$A$1:$A$10, 0) + 1), VLOOKUP($A14,'Data Feed (40C)'!$A$1:$G$10,2,FALSE))))} -> JKS240702ERIMON_40C_sample_1 | C14: {=IF(ISBLANK(A14),"",IF(A14="PROREP (L)",VLOOKUP(LEFT($A14,6),'Data Feed (40C)'!$A$1:$G$10,3,FALSE),IF(A14="PROREP (S)", INDEX('Data Feed (40C)'!C:C, MATCH(LEFT($A14,6), 'Data Feed (40C)'!$A$1:$A$10, 0) + 1, +1), VLOOKUP($A14,'Data Feed (40C)'!$A$1:$G$10,3,FALSE))))} -> Erica monsoniana | D14: {=IF(ISBLANK(A14),"",IF(A14="PROREP (L)",VLOOKUP(LEFT($A14,6),'Data Feed (40C)'!$A$1:$G$10,4,FALSE),IF(A14="PROREP (S)", INDEX('Data Feed (40C)'!D:D, MATCH(LEFT($A14,6), 'Data Feed (40C)'!$A$1:$A$10, 0) + 1, +1), VLOOKUP($A14,'Data Feed (40C)'!$A$1:$G$10,4,FALSE))))} -> 40C | E14: {=IF(ISBLANK(A14),"",IF(A14="PROREP (L)",VLOOKUP(LEFT($A14,6),'Data Feed (40C)'!$A$1:$G$10,7,FALSE),IF(A14="PROREP (S)", INDEX('Data Feed (40C)'!G:G, MATCH(LEFT($A14,6), 'Data Feed (40C)'!$A$1:$A$10, 0) + 1, +1), VLOOKUP($A14,'Data Feed (40C)'!$A$1:$G$10,7,FALSE))))} -> 1 | F14: 45477.573 | G14: 1.508
A15: =A14 -> ERIMON | B15: =IF(ISBLANK(A14),"",LEFT(B14,27)&VALUE(RIGHT(B14,1)+1)) -> JKS240702ERIMON_40C_sample_2 | C15: =C14 -> Erica monsoniana | D15: =D14 -> 40C | E15: =IF(ISBLANK(A14),"",E14+1) -> 2 | F15: =F14 -> 45477.573 | G15: 1.374
A16: =A15 -> ERIMON | B16: =IF(ISBLANK(A14),"",LEFT(B15,27)&VALUE(RIGHT(B15,1)+1)) -> JKS240702ERIMON_40C_sample_3 | C16: =C15 -> Erica monsoniana | D16: =D15 -> 40C | E16: =IF(ISBLANK(A14),"",E15+1) -> 3 | F16: =F15 -> 45477.573 | G16: 1.22
A17: =A16 -> ERIMON | B17: =IF(ISBLANK(A14),"",LEFT(B16,27)&VALUE(RIGHT(B16,1)+1)) -> JKS240702ERIMON_40C_sample_4 | C17: =C16 -> Erica monsoniana | D17: =D16 -> 40C | E17: =IF(ISBLANK(A14),"",E16+1) -> 4 | F17: =F16 -> 45477.573 | G17: 2.876
A18: =A17 -> ERIMON | B18: =IF(ISBLANK(A14),"",LEFT(B17,27)&VALUE(RIGHT(B17,1)+1)) -> JKS240702ERIMON_40C_sample_5 | C18: =C17 -> Erica monsoniana | D18: =D17 -> 40C | E18: =IF(ISBLANK(A14),"",E17+1) -> 5 | F18: =F17 -> 45477.573 | G18: 0.993
A19: =A18 -> ERIMON | B19: =IF(ISBLANK(A14),"",LEFT(B18,27)&VALUE(RIGHT(B18,1)+1)) -> JKS240702ERIMON_40C_sample_6 | C19: =C18 -> Erica monsoniana | D19: =D18 -> 40C | E19: =IF(ISBLANK(A14),"",E18+1) -> 6 | F19: =F18 -> 45477.573 | G19: 1.855
A20: PROREP (S) | B20: {=IF(ISBLANK(A20),"",IF(A20="PROREP (L)",VLOOKUP(LEFT($A20,6),'Data Feed (40C)'!$A$1:$G$10,2,FALSE),IF(A20="PROREP (S)", INDEX('Data Feed (40C)'!B:B, MATCH(LEFT($A20,6), 'Data Feed (40C)'!$A$1:$A$10, 0) + 1), VLOOKUP($A20,'Data Feed (40C)'!$A$1:$G$10,2,FALSE))))} -> JKS240702PROREP_40C_sample_1 | C20: {=IF(ISBLANK(A20),"",IF(A20="PROREP (L)",VLOOKUP(LEFT($A20,6),'Data Feed (40C)'!$A$1:$G$10,3,FALSE),IF(A20="PROREP (S)", INDEX('Data Feed (40C)'!C:C, MATCH(LEFT($A20,6), 'Data Feed (40C)'!$A$1:$A$10, 0) + 1, +1), VLOOKUP($A20,'Data Feed (40C)'!$A$1:$G$10,3,FALSE))))} -> Protea repens | D20: {=IF(ISBLANK(A20),"",IF(A20="PROREP (L)",VLOOKUP(LEFT($A20,6),'Data Feed (40C)'!$A$1:$G$10,4,FALSE),IF(A20="PROREP (S)", INDEX('Data Feed (40C)'!D:D, MATCH(LEFT($A20,6), 'Data Feed (40C)'!$A$1:$A$10, 0) + 1, +1), VLOOKUP($A20,'Data Feed (40C)'!$A$1:$G$10,4,FALSE))))} -> 40C | E20: {=IF(ISBLANK(A20),"",IF(A20="PROREP (L)",VLOOKUP(LEFT($A20,6),'Data Feed (40C)'!$A$1:$G$10,7,FALSE),IF(A20="PROREP (S)", INDEX('Data Feed (40C)'!G:G, MATCH(LEFT($A20,6), 'Data Feed (40C)'!$A$1:$A$10, 0) + 1, +1), VLOOKUP($A20,'Data Feed (40C)'!$A$1:$G$10,7,FALSE))))} -> 1 | F20: 45477.609 | G20: 7.292
A21: =A20 -> PROREP (S) | B21: =IF(ISBLANK(A20),"",LEFT(B20,27)&VALUE(RIGHT(B20,1)+1)) -> JKS240702PROREP_40C_sample_2 | C21: =C20 -> Protea repens | D21: =D20 -> 40C | E21: =IF(ISBLANK(A20),"",E20+1) -> 2 | F21: =F20 -> 45477.609 | G21: 11.855
A22: =A21 -> PROREP (S) | B22: =IF(ISBLANK(A20),"",LEFT(B21,27)&VALUE(RIGHT(B21,1)+1)) -> JKS240702PROREP_40C_sample_3 | C22: =C21 -> Protea repens | D22: =D21 -> 40C | E22: =IF(ISBLANK(A20),"",E21+1) -> 3 | F22: =F21 -> 45477.609 | G22: 4.825
A23: =A22 -> PROREP (S) | B23: =IF(ISBLANK(A20),"",LEFT(B22,27)&VALUE(RIGHT(B22,1)+1)) -> JKS240702PROREP_40C_sample_4 | C23: =C22 -> Protea repens | D23: =D22 -> 40C | E23: =IF(ISBLANK(A20),"",E22+1) -> 4 | F23: =F22 -> 45477.609 | G23: 1.779
A24: =A23 -> PROREP (S) | B24: =IF(ISBLANK(A20),"",LEFT(B23,27)&VALUE(RIGHT(B23,1)+1)) -> JKS240702PROREP_40C_sample_5 | C24: =C23 -> Protea repens | D24: =D23 -> 40C | E24: =IF(ISBLANK(A20),"",E23+1) -> 5 | F24: =F23 -> 45477.609 | G24: 7.849
A25: =A24 -> PROREP (S) | B25: =IF(ISBLANK(A20),"",LEFT(B24,27)&VALUE(RIGHT(B24,1)+1)) -> JKS240702PROREP_40C_sample_6 | C25: =C24 -> Protea repens | D25: =D24 -> 40C | E25: =IF(ISBLANK(A20),"",E24+1) -> 6 | F25: =F24 -> 45477.609 | G25: 10.937
A26: ERIMON | B26: {=IF(ISBLANK(A26),"",IF(A26="PROREP (L)",VLOOKUP(LEFT($A26,6),'Data Feed (40C)'!$A$1:$G$10,2,FALSE),IF(A26="PROREP (S)", INDEX('Data Feed (40C)'!B:B, MATCH(LEFT($A26,6), 'Data Feed (40C)'!$A$1:$A$10, 0) + 1), VLOOKUP($A26,'Data Feed (40C)'!$A$1:$G$10,2,FALSE))))} -> JKS240702ERIMON_40C_sample_1 | C26: {=IF(ISBLANK(A26),"",IF(A26="PROREP (L)",VLOOKUP(LEFT($A26,6),'Data Feed (40C)'!$A$1:$G$10,3,FALSE),IF(A26="PROREP (S)", INDEX('Data Feed (40C)'!C:C, MATCH(LEFT($A26,6), 'Data Feed (40C)'!$A$1:$A$10, 0) + 1, +1), VLOOKUP($A26,'Data Feed (40C)'!$A$1:$G$10,3,FALSE))))} -> Erica monsoniana | D26: {=IF(ISBLANK(A26),"",IF(A26="PROREP (L)",VLOOKUP(LEFT($A26,6),'Data Feed (40C)'!$A$1:$G$10,4,FALSE),IF(A26="PROREP (S)", INDEX('Data Feed (40C)'!D:D, MATCH(LEFT($A26,6), 'Data Feed (40C)'!$A$1:$A$10, 0) + 1, +1), VLOOKUP($A26,'Data Feed (40C)'!$A$1:$G$10,4,FALSE))))} -> 40C | E26: {=IF(ISBLANK(A26),"",IF(A26="PROREP (L)",VLOOKUP(LEFT($A26,6),'Data Feed (40C)'!$A$1:$G$10,7,FALSE),IF(A26="PROREP (S)", INDEX('Data Feed (40C)'!G:G, MATCH(LEFT($A26,6), 'Data Feed (40C)'!$A$1:$A$10, 0) + 1, +1), VLOOKUP($A26,'Data Feed (40C)'!$A$1:$G$10,7,FALSE))))} -> 1 | F26: 45477.61 | G26: 1.336
A27: =A26 -> ERIMON | B27: =IF(ISBLANK(A26),"",LEFT(B26,27)&VALUE(RIGHT(B26,1)+1)) -> JKS240702ERIMON_40C_sample_2 | C27: =C26 -> Erica monsoniana | D27: =D26 -> 40C | E27: =IF(ISBLANK(A26),"",E26+1) -> 2 | F27: =F26 -> 45477.61 | G27: 1.2
A28: =A27 -> ERIMON | B28: =IF(ISBLANK(A26),"",LEFT(B27,27)&VALUE(RIGHT(B27,1)+1)) -> JKS240702ERIMON_40C_sample_3 | C28: =C27 -> Erica monsoniana | D28: =D27 -> 40C | E28: =IF(ISBLANK(A26),"",E27+1) -> 3 | F28: =F27 -> 45477.61 | G28: 1.07
A29: =A28 -> ERIMON | B29: =IF(ISBLANK(A26),"",LEFT(B28,27)&VALUE(RIGHT(B28,1)+1)) -> JKS240702ERIMON_40C_sample_4 | C29: =C28 -> Erica monsoniana | D29: =D28 -> 40C | E29: =IF(ISBLANK(A26),"",E28+1) -> 4 | F29: =F28 -> 45477.61 | G29: 2.598
A30: =A29 -> ERIMON | B30: =IF(ISBLANK(A26),"",LEFT(B29,27)&VALUE(RIGHT(B29,1)+1)) -> JKS240702ERIMON_40C_sample_5 | C30: =C29 -> Erica monsoniana | D30: =D29 -> 40C | E30: =IF(ISBLANK(A26),"",E29+1) -> 5 | F30: =F29 -> 45477.61 | G30: 0.892
A31: =A30 -> ERIMON | B31: =IF(ISBLANK(A26),"",LEFT(B30,27)&VALUE(RIGHT(B30,1)+1)) -> JKS240702ERIMON_40C_sample_6 | C31: =C30 -> Erica monsoniana | D31: =D30 -> 40C | E31: =IF(ISBLANK(A26),"",E30+1) -> 6 | F31: =F30 -> 45477.61 | G31: 1.608
A32: PROREP (L) | B32: {=IF(ISBLANK(A32),"",IF(A32="PROREP (L)",VLOOKUP(LEFT($A32,6),'Data Feed (40C)'!$A$1:$G$10,2,FALSE),IF(A32="PROREP (S)", INDEX('Data Feed (40C)'!B:B, MATCH(LEFT($A32,6), 'Data Feed (40C)'!$A$1:$A$10, 0) + 1), VLOOKUP($A32,'Data Feed (40C)'!$A$1:$G$10,2,FALSE))))} -> JKL240702PROREP_40C_sample_1 | C32: {=IF(ISBLANK(A32),"",IF(A32="PROREP (L)",VLOOKUP(LEFT($A32,6),'Data Feed (40C)'!$A$1:$G$10,3,FALSE),IF(A32="PROREP (S)", INDEX('Data Feed (40C)'!C:C, MATCH(LEFT($A32,6), 'Data Feed (40C)'!$A$1:$A$10, 0) + 1, +1), VLOOKUP($A32,'Data Feed (40C)'!$A$1:$G$10,3,FALSE))))} -> Protea repens | D32: {=IF(ISBLANK(A32),"",IF(A32="PROREP (L)",VLOOKUP(LEFT($A32,6),'Data Feed (40C)'!$A$1:$G$10,4,FALSE),IF(A32="PROREP (S)", INDEX('Data Feed (40C)'!D:D, MATCH(LEFT($A32,6), 'Data Feed (40C)'!$A$1:$A$10, 0) + 1, +1), VLOOKUP($A32,'Data Feed (40C)'!$A$1:$G$10,4,FALSE))))} -> 40C | E32: {=IF(ISBLANK(A32),"",IF(A32="PROREP (L)",VLOOKUP(LEFT($A32,6),'Data Feed (40C)'!$A$1:$G$10,7,FALSE),IF(A32="PROREP (S)", INDEX('Data Feed (40C)'!G:G, MATCH(LEFT($A32,6), 'Data Feed (40C)'!$A$1:$A$10, 0) + 1, +1), VLOOKUP($A32,'Data Feed (40C)'!$A$1:$G$10,7,FALSE))))} -> 1 | F32: 45477.612 | G32: 0.564
A33: =A32 -> PROREP (L) | B33: =IF(ISBLANK(A32),"",LEFT(B32,27)&VALUE(RIGHT(B32,1)+1)) -> JKL240702PROREP_40C_sample_2 | C33: =C32 -> Protea repens | D33: =D32 -> 40C | E33: =IF(ISBLANK(A32),"",E32+1) -> 2 | F33: =F32 -> 45477.612 | G33: 0.491
A34: =A33 -> PROREP (L) | B34: =IF(ISBLANK(A32),"",LEFT(B33,27)&VALUE(RIGHT(B33,1)+1)) -> JKL240702PROREP_40C_sample_3 | C34: =C33 -> Protea repens | D34: =D33 -> 40C | E34: =IF(ISBLANK(A32),"",E33+1) -> 3 | F34: =F33 -> 45477.612 | G34: 0.605
A35: =A34 -> PROREP (L) | B35: =IF(ISBLANK(A32),"",LEFT(B34,27)&VALUE(RIGHT(B34,1)+1)) -> JKL240702PROREP_40C_sample_4 | C35: =C34 -> Protea repens | D35: =D34 -> 40C | E35: =IF(ISBLANK(A32),"",E34+1) -> 4 | F35: =F34 -> 45477.612 | G35: 0.27
A36: =A35 -> PROREP (L) | B36: =IF(ISBLANK(A32),"",LEFT(B35,27)&VALUE(RIGHT(B35,1)+1)) -> JKL240702PROREP_40C_sample_5 | C36: =C35 -> Protea repens | D36: =D35 -> 40C | E36: =IF(ISBLANK(A32),"",E35+1) -> 5 | F36: =F35 -> 45477.612 | G36: 0.341
A37: =A36 -> PROREP (L) | B37: =IF(ISBLANK(A32),"",LEFT(B36,27)&VALUE(RIGHT(B36,1)+1)) -> JKL240702PROREP_40C_sample_6 | C37: =C36 -> Protea repens | D37: =D36 -> 40C | E37: =IF(ISBLANK(A32),"",E36+1) -> 6 | F37: =F36 -> 45477.612 | G37: 0.431
A38: ERIMON | B38: {=IF(ISBLANK(A38),"",IF(A38="PROREP (L)",VLOOKUP(LEFT($A38,6),'Data Feed (40C)'!$A$1:$G$10,2,FALSE),IF(A38="PROREP (S)", INDEX('Data Feed (40C)'!B:B, MATCH(LEFT($A38,6), 'Data Feed (40C)'!$A$1:$A$10, 0) + 1), VLOOKUP($A38,'Data Feed (40C)'!$A$1:$G$10,2,FALSE))))} -> JKS240702ERIMON_40C_sample_1 | C38: {=IF(ISBLANK(A38),"",IF(A38="PROREP (L)",VLOOKUP(LEFT($A38,6),'Data Feed (40C)'!$A$1:$G$10,3,FALSE),IF(A38="PROREP (S)", INDEX('Data Feed (40C)'!C:C, MATCH(LEFT($A38,6), 'Data Feed (40C)'!$A$1:$A$10, 0) + 1, +1), VLOOKUP($A38,'Data Feed (40C)'!$A$1:$G$10,3,FALSE))))} -> Erica monsoniana | D38: {=IF(ISBLANK(A38),"",IF(A38="PROREP (L)",VLOOKUP(LEFT($A38,6),'Data Feed (40C)'!$A$1:$G$10,4,FALSE),IF(A38="PROREP (S)", INDEX('Data Feed (40C)'!D:D, MATCH(LEFT($A38,6), 'Data Feed (40C)'!$A$1:$A$10, 0) + 1, +1), VLOOKUP($A38,'Data Feed (40C)'!$A$1:$G$10,4,FALSE))))} -> 40C | E38: {=IF(ISBLANK(A38),"",IF(A38="PROREP (L)",VLOOKUP(LEFT($A38,6),'Data Feed (40C)'!$A$1:$G$10,7,FALSE),IF(A38="PROREP (S)", INDEX('Data Feed (40C)'!G:G, MATCH(LEFT($A38,6), 'Data Feed (40C)'!$A$1:$A$10, 0) + 1, +1), VLOOKUP($A38,'Data Feed (40C)'!$A$1:$G$10,7,FALSE))))} -> 1 | F38: 45477.656 | G38: 1.166
A39: =A38 -> ERIMON | B39: =IF(ISBLANK(A38),"",LEFT(B38,27)&VALUE(RIGHT(B38,1)+1)) -> JKS240702ERIMON_40C_sample_2 | C39: =C38 -> Erica monsoniana | D39: =D38 -> 40C | E39: =IF(ISBLANK(A38),"",E38+1) -> 2 | F39: =F38 -> 45477.656 | G39: 1.068
A40: =A39 -> ERIMON | B40: =IF(ISBLANK(A38),"",LEFT(B39,27)&VALUE(RIGHT(B39,1)+1)) -> JKS240702ERIMON_40C_sample_3 | C40: =C39 -> Erica monsoniana | D40: =D39 -> 40C | E40: =IF(ISBLANK(A38),"",E39+1) -> 3 | F40: =F39 -> 45477.656 | G40: 0.94
...

Sheet 35C
A1: GENSPP | B1: ID_Code | C1: Species | D1: Treat | E1: Sample_no | F1: Date_Time | G1: Weight
A2: ERIMON | B2: {=IF(ISBLANK(A2),"",IF(A2="PROREP (L)",VLOOKUP(LEFT($A2,6),'Data Feed (35C)'!$A$1:$G$10,2,FALSE),IF(A2="PROREP (S)", INDEX('Data Feed (35C)'!B:B, MATCH(LEFT($A2,6), 'Data Feed (35C)'!$A$1:$A$10, 0) + 1), VLOOKUP($A2,'Data Feed (35C)'!$A$1:$G$10,2,FALSE))))} -> JKS240702ERIMON_35C_sample_1 | C2: {=IF(ISBLANK(A2),"",IF(A2="PROREP (L)",VLOOKUP(LEFT($A2,6),'Data Feed (35C)'!$A$1:$G$10,3,FALSE),IF(A2="PROREP (S)", INDEX('Data Feed (35C)'!C:C, MATCH(LEFT($A2,6), 'Data Feed (35C)'!$A$1:$A$10, 0) + 1, +1), VLOOKUP($A2,'Data Feed (35C)'!$A$1:$G$10,3,FALSE))))} -> Erica monsoniana | D2: {=IF(ISBLANK(A2),"",IF(A2="PROREP (L)",VLOOKUP(LEFT($A2,6),'Data Feed (35C)'!$A$1:$G$10,4,FALSE),IF(A2="PROREP (S)", INDEX('Data Feed (35C)'!D:D, MATCH(LEFT($A2,6), 'Data Feed (35C)'!$A$1:$A$10, 0) + 1, +1), VLOOKUP($A2,'Data Feed (35C)'!$A$1:$G$10,4,FALSE))))} -> 35C | E2: {=IF(ISBLANK(A2),"",IF(A2="PROREP (L)",VLOOKUP(LEFT($A2,6),'Data Feed (35C)'!$A$1:$G$10,7,FALSE),IF(A2="PROREP (S)", INDEX('Data Feed (35C)'!G:G, MATCH(LEFT($A2,6), 'Data Feed (35C)'!$A$1:$A$10, 0) + 1, +1), VLOOKUP($A2,'Data Feed (35C)'!$A$1:$G$10,7,FALSE))))} -> 1 | F2: 45477.524 | G2: 4.059
A3: =A2 -> ERIMON | B3: =IF(ISBLANK(A2),"",LEFT(B2,27)&VALUE(RIGHT(B2,1)+1)) -> JKS240702ERIMON_35C_sample_2 | C3: =C2 -> Erica monsoniana | D3: =D2 -> 35C | E3: =IF(ISBLANK(A2),"",E2+1) -> 2 | F3: =F2 -> 45477.524 | G3: 2.262
A4: =A3 -> ERIMON | B4: =IF(ISBLANK(A2),"",LEFT(B3,27)&VALUE(RIGHT(B3,1)+1)) -> JKS240702ERIMON_35C_sample_3 | C4: =C3 -> Erica monsoniana | D4: =D3 -> 35C | E4: =IF(ISBLANK(A2),"",E3+1) -> 3 | F4: =F3 -> 45477.524 | G4: 0.75
A5: =A4 -> ERIMON | B5: =IF(ISBLANK(A2),"",LEFT(B4,27)&VALUE(RIGHT(B4,1)+1)) -> JKS240702ERIMON_35C_sample_4 | C5: =C4 -> Erica monsoniana | D5: =D4 -> 35C | E5: =IF(ISBLANK(A2),"",E4+1) -> 4 | F5: =F4 -> 45477.524 | G5: 1.219
A6: =A5 -> ERIMON | B6: =IF(ISBLANK(A2),"",LEFT(B5,27)&VALUE(RIGHT(B5,1)+1)) -> JKS240702ERIMON_35C_sample_5 | C6: =C5 -> Erica monsoniana | D6: =D5 -> 35C | E6: =IF(ISBLANK(A2),"",E5+1) -> 5 | F6: =F5 -> 45477.524 | G6: 3.436
A7: =A6 -> ERIMON | B7: =IF(ISBLANK(A2),"",LEFT(B6,27)&VALUE(RIGHT(B6,1)+1)) -> JKS240702ERIMON_35C_sample_6 | C7: =C6 -> Erica monsoniana | D7: =D6 -> 35C | E7: =IF(ISBLANK(A2),"",E6+1) -> 6 | F7: =F6 -> 45477.524 | G7: 1.146
A8: PROREP (L) | B8: {=IF(ISBLANK(A8),"",IF(A8="PROREP (L)",VLOOKUP(LEFT($A8,6),'Data Feed (35C)'!$A$1:$G$10,2,FALSE),IF(A8="PROREP (S)", INDEX('Data Feed (35C)'!B:B, MATCH(LEFT($A8,6), 'Data Feed (35C)'!$A$1:$A$10, 0) + 1), VLOOKUP($A8,'Data Feed (35C)'!$A$1:$G$10,2,FALSE))))} -> JKL240702PROREP_35C_sample_1 | C8: {=IF(ISBLANK(A8),"",IF(A8="PROREP (L)",VLOOKUP(LEFT($A8,6),'Data Feed (35C)'!$A$1:$G$10,3,FALSE),IF(A8="PROREP (S)", INDEX('Data Feed (35C)'!C:C, MATCH(LEFT($A8,6), 'Data Feed (35C)'!$A$1:$A$10, 0) + 1, +1), VLOOKUP($A8,'Data Feed (35C)'!$A$1:$G$10,3,FALSE))))} -> Protea repens | D8: {=IF(ISBLANK(A8),"",IF(A8="PROREP (L)",VLOOKUP(LEFT($A8,6),'Data Feed (35C)'!$A$1:$G$10,4,FALSE),IF(A8="PROREP (S)", INDEX('Data Feed (35C)'!D:D, MATCH(LEFT($A8,6), 'Data Feed (35C)'!$A$1:$A$10, 0) + 1, +1), VLOOKUP($A8,'Data Feed (35C)'!$A$1:$G$10,4,FALSE))))} -> 35C | E8: {=IF(ISBLANK(A8),"",IF(A8="PROREP (L)",VLOOKUP(LEFT($A8,6),'Data Feed (35C)'!$A$1:$G$10,7,FALSE),IF(A8="PROREP (S)", INDEX('Data Feed (35C)'!G:G, MATCH(LEFT($A8,6), 'Data Feed (35C)'!$A$1:$A$10, 0) + 1, +1), VLOOKUP($A8,'Data Feed (35C)'!$A$1:$G$10,7,FALSE))))} -> 1 | F8: 45477.572 | G8: 0.526
A9: =A8 -> PROREP (L) | B9: =IF(ISBLANK(A8),"",LEFT(B8,27)&VALUE(RIGHT(B8,1)+1)) -> JKL240702PROREP_35C_sample_2 | C9: =C8 -> Protea repens | D9: =D8 -> 35C | E9: =IF(ISBLANK(A8),"",E8+1) -> 2 | F9: =F8 -> 45477.572 | G9: 0.608
A10: =A9 -> PROREP (L) | B10: =IF(ISBLANK(A8),"",LEFT(B9,27)&VALUE(RIGHT(B9,1)+1)) -> JKL240702PROREP_35C_sample_3 | C10: =C9 -> Protea repens | D10: =D9 -> 35C | E10: =IF(ISBLANK(A8),"",E9+1) -> 3 | F10: =F9 -> 45477.572 | G10: 0.809
A11: =A10 -> PROREP (L) | B11: =IF(ISBLANK(A8),"",LEFT(B10,27)&VALUE(RIGHT(B10,1)+1)) -> JKL240702PROREP_35C_sample_4 | C11: =C10 -> Protea repens | D11: =D10 -> 35C | E11: =IF(ISBLANK(A8),"",E10+1) -> 4 | F11: =F10 -> 45477.572 | G11: 0.531
A12: =A11 -> PROREP (L) | B12: =IF(ISBLANK(A8),"",LEFT(B11,27)&VALUE(RIGHT(B11,1)+1)) -> JKL240702PROREP_35C_sample_5 | C12: =C11 -> Protea repens | D12: =D11 -> 35C | E12: =IF(ISBLANK(A8),"",E11+1) -> 5 | F12: =F11 -> 45477.572 | G12: 0.465
A13: =A12 -> PROREP (L) | B13: =IF(ISBLANK(A8),"",LEFT(B12,27)&VALUE(RIGHT(B12,1)+1)) -> JKL240702PROREP_35C_sample_6 | C13: =C12 -> Protea repens | D13: =D12 -> 35C | E13: =IF(ISBLANK(A8),"",E12+1) -> 6 | F13: =F12 -> 45477.572 | G13: 0.397
A14: ERIMON | B14: {=IF(ISBLANK(A14),"",IF(A14="PROREP (L)",VLOOKUP(LEFT($A14,6),'Data Feed (35C)'!$A$1:$G$10,2,FALSE),IF(A14="PROREP (S)", INDEX('Data Feed (35C)'!B:B, MATCH(LEFT($A14,6), 'Data Feed (35C)'!$A$1:$A$10, 0) + 1), VLOOKUP($A14,'Data Feed (35C)'!$A$1:$G$10,2,FALSE))))} -> JKS240702ERIMON_35C_sample_1 | C14: {=IF(ISBLANK(A14),"",IF(A14="PROREP (L)",VLOOKUP(LEFT($A14,6),'Data Feed (35C)'!$A$1:$G$10,3,FALSE),IF(A14="PROREP (S)", INDEX('Data Feed (35C)'!C:C, MATCH(LEFT($A14,6), 'Data Feed (35C)'!$A$1:$A$10, 0) + 1, +1), VLOOKUP($A14,'Data Feed (35C)'!$A$1:$G$10,3,FALSE))))} -> Erica monsoniana | D14: {=IF(ISBLANK(A14),"",IF(A14="PROREP (L)",VLOOKUP(LEFT($A14,6),'Data Feed (35C)'!$A$1:$G$10,4,FALSE),IF(A14="PROREP (S)", INDEX('Data Feed (35C)'!D:D, MATCH(LEFT($A14,6), 'Data Feed (35C)'!$A$1:$A$10, 0) + 1, +1), VLOOKUP($A14,'Data Feed (35C)'!$A$1:$G$10,4,FALSE))))} -> 35C | E14: {=IF(ISBLANK(A14),"",IF(A14="PROREP (L)",VLOOKUP(LEFT($A14,6),'Data Feed (35C)'!$A$1:$G$10,7,FALSE),IF(A14="PROREP (S)", INDEX('Data Feed (35C)'!G:G, MATCH(LEFT($A14,6), 'Data Feed (35C)'!$A$1:$A$10, 0) + 1, +1), VLOOKUP($A14,'Data Feed (35C)'!$A$1:$G$10,7,FALSE))))} -> 1 | F14: 45477.576 | G14: 3.677
A15: =A14 -> ERIMON | B15: =IF(ISBLANK(A14),"",LEFT(B14,27)&VALUE(RIGHT(B14,1)+1)) -> JKS240702ERIMON_35C_sample_2 | C15: =C14 -> Erica monsoniana | D15: =D14 -> 35C | E15: =IF(ISBLANK(A14),"",E14+1) -> 2 | F15: =F14 -> 45477.576 | G15: 2.045
A16: =A15 -> ERIMON | B16: =IF(ISBLANK(A14),"",LEFT(B15,27)&VALUE(RIGHT(B15,1)+1)) -> JKS240702ERIMON_35C_sample_3 | C16: =C15 -> Erica monsoniana | D16: =D15 -> 35C | E16: =IF(ISBLANK(A14),"",E15+1) -> 3 | F16: =F15 -> 45477.576 | G16: 0.668
A17: =A16 -> ERIMON | B17: =IF(ISBLANK(A14),"",LEFT(B16,27)&VALUE(RIGHT(B16,1)+1)) -> JKS240702ERIMON_35C_sample_4 | C17: =C16 -> Erica monsoniana | D17: =D16 -> 35C | E17: =IF(ISBLANK(A14),"",E16+1) -> 4 | F17: =F16 -> 45477.576 | G17: 1.113
A18: =A17 -> ERIMON | B18: =IF(ISBLANK(A14),"",LEFT(B17,27)&VALUE(RIGHT(B17,1)+1)) -> JKS240702ERIMON_35C_sample_5 | C18: =C17 -> Erica monsoniana | D18: =D17 -> 35C | E18: =IF(ISBLANK(A14),"",E17+1) -> 5 | F18: =F17 -> 45477.576 | G18: 3.155
A19: =A18 -> ERIMON | B19: =IF(ISBLANK(A14),"",LEFT(B18,27)&VALUE(RIGHT(B18,1)+1)) -> JKS240702ERIMON_35C_sample_6 | C19: =C18 -> Erica monsoniana | D19: =D18 -> 35C | E19: =IF(ISBLANK(A14),"",E18+1) -> 6 | F19: =F18 -> 45477.576 | G19: 1.026
A20: PROREP (S) | B20: {=IF(ISBLANK(A20),"",IF(A20="PROREP (L)",VLOOKUP(LEFT($A20,6),'Data Feed (35C)'!$A$1:$G$10,2,FALSE),IF(A20="PROREP (S)", INDEX('Data Feed (35C)'!B:B, MATCH(LEFT($A20,6), 'Data Feed (35C)'!$A$1:$A$10, 0) + 1), VLOOKUP($A20,'Data Feed (35C)'!$A$1:$G$10,2,FALSE))))} -> JKS240702PROREP_35C_sample_1 | C20: {=IF(ISBLANK(A20),"",IF(A20="PROREP (L)",VLOOKUP(LEFT($A20,6),'Data Feed (35C)'!$A$1:$G$10,3,FALSE),IF(A20="PROREP (S)", INDEX('Data Feed (35C)'!C:C, MATCH(LEFT($A20,6), 'Data Feed (35C)'!$A$1:$A$10, 0) + 1, +1), VLOOKUP($A20,'Data Feed (35C)'!$A$1:$G$10,3,FALSE))))} -> Protea repens | D20: {=IF(ISBLANK(A20),"",IF(A20="PROREP (L)",VLOOKUP(LEFT($A20,6),'Data Feed (35C)'!$A$1:$G$10,4,FALSE),IF(A20="PROREP (S)", INDEX('Data Feed (35C)'!D:D, MATCH(LEFT($A20,6), 'Data Feed (35C)'!$A$1:$A$10, 0) + 1, +1), VLOOKUP($A20,'Data Feed (35C)'!$A$1:$G$10,4,FALSE))))} -> 35C | E20: {=IF(ISBLANK(A20),"",IF(A20="PROREP (L)",VLOOKUP(LEFT($A20,6),'Data Feed (35C)'!$A$1:$G$10,7,FALSE),IF(A20="PROREP (S)", INDEX('Data Feed (35C)'!G:G, MATCH(LEFT($A20,6), 'Data Feed (35C)'!$A$1:$A$10, 0) + 1, +1), VLOOKUP($A20,'Data Feed (35C)'!$A$1:$G$10,7,FALSE))))} -> 1 | F20: 45477.609 | G20: 10.06
A21: =A20 -> PROREP (S) | B21: =IF(ISBLANK(A20),"",LEFT(B20,27)&VALUE(RIGHT(B20,1)+1)) -> JKS240702PROREP_35C_sample_2 | C21: =C20 -> Protea repens | D21: =D20 -> 35C | E21: =IF(ISBLANK(A20),"",E20+1) -> 2 | F21: =F20 -> 45477.609 | G21: 19.412
A22: =A21 -> PROREP (S) | B22: =IF(ISBLANK(A20),"",LEFT(B21,27)&VALUE(RIGHT(B21,1)+1)) -> JKS240702PROREP_35C_sample_3 | C22: =C21 -> Protea repens | D22: =D21 -> 35C | E22: =IF(ISBLANK(A20),"",E21+1) -> 3 | F22: =F21 -> 45477.609 | G22: 19.631
A23: =A22 -> PROREP (S) | B23: =IF(ISBLANK(A20),"",LEFT(B22,27)&VALUE(RIGHT(B22,1)+1)) -> JKS240702PROREP_35C_sample_4 | C23: =C22 -> Protea repens | D23: =D22 -> 35C | E23: =IF(ISBLANK(A20),"",E22+1) -> 4 | F23: =F22 -> 45477.609 | G23: 4.052
A24: =A23 -> PROREP (S) | B24: =IF(ISBLANK(A20),"",LEFT(B23,27)&VALUE(RIGHT(B23,1)+1)) -> JKS240702PROREP_35C_sample_5 | C24: =C23 -> Protea repens | D24: =D23 -> 35C | E24: =IF(ISBLANK(A20),"",E23+1) -> 5 | F24: =F23 -> 45477.609 | G24: 5.8
A25: =A24 -> PROREP (S) | B25: =IF(ISBLANK(A20),"",LEFT(B24,27)&VALUE(RIGHT(B24,1)+1)) -> JKS240702PROREP_35C_sample_6 | C25: =C24 -> Protea repens | D25: =D24 -> 35C | E25: =IF(ISBLANK(A20),"",E24+1) -> 6 | F25: =F24 -> 45477.609 | G25: 7.801
A26: ERIMON | B26: {=IF(ISBLANK(A26),"",IF(A26="PROREP (L)",VLOOKUP(LEFT($A26,6),'Data Feed (35C)'!$A$1:$G$10,2,FALSE),IF(A26="PROREP (S)", INDEX('Data Feed (35C)'!B:B, MATCH(LEFT($A26,6), 'Data Feed (35C)'!$A$1:$A$10, 0) + 1), VLOOKUP($A26,'Data Feed (35C)'!$A$1:$G$10,2,FALSE))))} -> JKS240702ERIMON_35C_sample_1 | C26: {=IF(ISBLANK(A26),"",IF(A26="PROREP (L)",VLOOKUP(LEFT($A26,6),'Data Feed (35C)'!$A$1:$G$10,3,FALSE),IF(A26="PROREP (S)", INDEX('Data Feed (35C)'!C:C, MATCH(LEFT($A26,6), 'Data Feed (35C)'!$A$1:$A$10, 0) + 1, +1), VLOOKUP($A26,'Data Feed (35C)'!$A$1:$G$10,3,FALSE))))} -> Erica monsoniana | D26: {=IF(ISBLANK(A26),"",IF(A26="PROREP (L)",VLOOKUP(LEFT($A26,6),'Data Feed (35C)'!$A$1:$G$10,4,FALSE),IF(A26="PROREP (S)", INDEX('Data Feed (35C)'!D:D, MATCH(LEFT($A26,6), 'Data Feed (35C)'!$A$1:$A$10, 0) + 1, +1), VLOOKUP($A26,'Data Feed (35C)'!$A$1:$G$10,4,FALSE))))} -> 35C | E26: {=IF(ISBLANK(A26),"",IF(A26="PROREP (L)",VLOOKUP(LEFT($A26,6),'Data Feed (35C)'!$A$1:$G$10,7,FALSE),IF(A26="PROREP (S)", INDEX('Data Feed (35C)'!G:G, MATCH(LEFT($A26,6), 'Data Feed (35C)'!$A$1:$A$10, 0) + 1, +1), VLOOKUP($A26,'Data Feed (35C)'!$A$1:$G$10,7,FALSE))))} -> 1 | F26: 45477.613 | G26: 3.521
A27: =A26 -> ERIMON | B27: =IF(ISBLANK(A26),"",LEFT(B26,27)&VALUE(RIGHT(B26,1)+1)) -> JKS240702ERIMON_35C_sample_2 | C27: =C26 -> Erica monsoniana | D27: =D26 -> 35C | E27: =IF(ISBLANK(A26),"",E26+1) -> 2 | F27: =F26 -> 45477.613 | G27: 1.97
A28: =A27 -> ERIMON | B28: =IF(ISBLANK(A26),"",LEFT(B27,27)&VALUE(RIGHT(B27,1)+1)) -> JKS240702ERIMON_35C_sample_3 | C28: =C27 -> Erica monsoniana | D28: =D27 -> 35C | E28: =IF(ISBLANK(A26),"",E27+1) -> 3 | F28: =F27 -> 45477.613 | G28: 0.649
A29: =A28 -> ERIMON | B29: =IF(ISBLANK(A26),"",LEFT(B28,27)&VALUE(RIGHT(B28,1)+1)) -> JKS240702ERIMON_35C_sample_4 | C29: =C28 -> Erica monsoniana | D29: =D28 -> 35C | E29: =IF(ISBLANK(A26),"",E28+1) -> 4 | F29: =F28 -> 45477.613 | G29: 1.061
A30: =A29 -> ERIMON | B30: =IF(ISBLANK(A26),"",LEFT(B29,27)&VALUE(RIGHT(B29,1)+1)) -> JKS240702ERIMON_35C_sample_5 | C30: =C29 -> Erica monsoniana | D30: =D29 -> 35C | E30: =IF(ISBLANK(A26),"",E29+1) -> 5 | F30: =F29 -> 45477.613 | G30: 3.015
A31: =A30 -> ERIMON | B31: =IF(ISBLANK(A26),"",LEFT(B30,27)&VALUE(RIGHT(B30,1)+1)) -> JKS240702ERIMON_35C_sample_6 | C31: =C30 -> Erica monsoniana | D31: =D30 -> 35C | E31: =IF(ISBLANK(A26),"",E30+1) -> 6 | F31: =F30 -> 45477.613 | G31: 0.949
A32: PROREP (L) | B32: {=IF(ISBLANK(A32),"",IF(A32="PROREP (L)",VLOOKUP(LEFT($A32,6),'Data Feed (35C)'!$A$1:$G$10,2,FALSE),IF(A32="PROREP (S)", INDEX('Data Feed (35C)'!B:B, MATCH(LEFT($A32,6), 'Data Feed (35C)'!$A$1:$A$10, 0) + 1), VLOOKUP($A32,'Data Feed (35C)'!$A$1:$G$10,2,FALSE))))} -> JKL240702PROREP_35C_sample_1 | C32: {=IF(ISBLANK(A32),"",IF(A32="PROREP (L)",VLOOKUP(LEFT($A32,6),'Data Feed (35C)'!$A$1:$G$10,3,FALSE),IF(A32="PROREP (S)", INDEX('Data Feed (35C)'!C:C, MATCH(LEFT($A32,6), 'Data Feed (35C)'!$A$1:$A$10, 0) + 1, +1), VLOOKUP($A32,'Data Feed (35C)'!$A$1:$G$10,3,FALSE))))} -> Protea repens | D32: {=IF(ISBLANK(A32),"",IF(A32="PROREP (L)",VLOOKUP(LEFT($A32,6),'Data Feed (35C)'!$A$1:$G$10,4,FALSE),IF(A32="PROREP (S)", INDEX('Data Feed (35C)'!D:D, MATCH(LEFT($A32,6), 'Data Feed (35C)'!$A$1:$A$10, 0) + 1, +1), VLOOKUP($A32,'Data Feed (35C)'!$A$1:$G$10,4,FALSE))))} -> 35C | E32: {=IF(ISBLANK(A32),"",IF(A32="PROREP (L)",VLOOKUP(LEFT($A32,6),'Data Feed (35C)'!$A$1:$G$10,7,FALSE),IF(A32="PROREP (S)", INDEX('Data Feed (35C)'!G:G, MATCH(LEFT($A32,6), 'Data Feed (35C)'!$A$1:$A$10, 0) + 1, +1), VLOOKUP($A32,'Data Feed (35C)'!$A$1:$G$10,7,FALSE))))} -> 1 | F32: 45477.614 | G32: 0.518
A33: =A32 -> PROREP (L) | B33: =IF(ISBLANK(A32),"",LEFT(B32,27)&VALUE(RIGHT(B32,1)+1)) -> JKL240702PROREP_35C_sample_2 | C33: =C32 -> Protea repens | D33: =D32 -> 35C | E33: =IF(ISBLANK(A32),"",E32+1) -> 2 | F33: =F32 -> 45477.614 | G33: 0.601
A34: =A33 -> PROREP (L) | B34: =IF(ISBLANK(A32),"",LEFT(B33,27)&VALUE(RIGHT(B33,1)+1)) -> JKL240702PROREP_35C_sample_3 | C34: =C33 -> Protea repens | D34: =D33 -> 35C | E34: =IF(ISBLANK(A32),"",E33+1) -> 3 | F34: =F33 -> 45477.614 | G34: 0.798
A35: =A34 -> PROREP (L) | B35: =IF(ISBLANK(A32),"",LEFT(B34,27)&VALUE(RIGHT(B34,1)+1)) -> JKL240702PROREP_35C_sample_4 | C35: =C34 -> Protea repens | D35: =D34 -> 35C | E35: =IF(ISBLANK(A32),"",E34+1) -> 4 | F35: =F34 -> 45477.614 | G35: 0.504
A36: =A35 -> PROREP (L) | B36: =IF(ISBLANK(A32),"",LEFT(B35,27)&VALUE(RIGHT(B35,1)+1)) -> JKL240702PROREP_35C_sample_5 | C36: =C35 -> Protea repens | D36: =D35 -> 35C | E36: =IF(ISBLANK(A32),"",E35+1) -> 5 | F36: =F35 -> 45477.614 | G36: 0.446
A37: =A36 -> PROREP (L) | B37: =IF(ISBLANK(A32),"",LEFT(B36,27)&VALUE(RIGHT(B36,1)+1)) -> JKL240702PROREP_35C_sample_6 | C37: =C36 -> Protea repens | D37: =D36 -> 35C | E37: =IF(ISBLANK(A32),"",E36+1) -> 6 | F37: =F36 -> 45477.614 | G37: 0.379
A38: ERIMON | B38: {=IF(ISBLANK(A38),"",IF(A38="PROREP (L)",VLOOKUP(LEFT($A38,6),'Data Feed (35C)'!$A$1:$G$10,2,FALSE),IF(A38="PROREP (S)", INDEX('Data Feed (35C)'!B:B, MATCH(LEFT($A38,6), 'Data Feed (35C)'!$A$1:$A$10, 0) + 1), VLOOKUP($A38,'Data Feed (35C)'!$A$1:$G$10,2,FALSE))))} -> JKS240702ERIMON_35C_sample_1 | C38: {=IF(ISBLANK(A38),"",IF(A38="PROREP (L)",VLOOKUP(LEFT($A38,6),'Data Feed (35C)'!$A$1:$G$10,3,FALSE),IF(A38="PROREP (S)", INDEX('Data Feed (35C)'!C:C, MATCH(LEFT($A38,6), 'Data Feed (35C)'!$A$1:$A$10, 0) + 1, +1), VLOOKUP($A38,'Data Feed (35C)'!$A$1:$G$10,3,FALSE))))} -> Erica monsoniana | D38: {=IF(ISBLANK(A38),"",IF(A38="PROREP (L)",VLOOKUP(LEFT($A38,6),'Data Feed (35C)'!$A$1:$G$10,4,FALSE),IF(A38="PROREP (S)", INDEX('Data Feed (35C)'!D:D, MATCH(LEFT($A38,6), 'Data Feed (35C)'!$A$1:$A$10, 0) + 1, +1), VLOOKUP($A38,'Data Feed (35C)'!$A$1:$G$10,4,FALSE))))} -> 35C | E38: {=IF(ISBLANK(A38),"",IF(A38="PROREP (L)",VLOOKUP(LEFT($A38,6),'Data Feed (35C)'!$A$1:$G$10,7,FALSE),IF(A38="PROREP (S)", INDEX('Data Feed (35C)'!G:G, MATCH(LEFT($A38,6), 'Data Feed (35C)'!$A$1:$A$10, 0) + 1, +1), VLOOKUP($A38,'Data Feed (35C)'!$A$1:$G$10,7,FALSE))))} -> 1 | F38: 45477.656 | G38: 3.306
A39: =A38 -> ERIMON | B39: =IF(ISBLANK(A38),"",LEFT(B38,27)&VALUE(RIGHT(B38,1)+1)) -> JKS240702ERIMON_35C_sample_2 | C39: =C38 -> Erica monsoniana | D39: =D38 -> 35C | E39: =IF(ISBLANK(A38),"",E38+1) -> 2 | F39: =F38 -> 45477.656 | G39: 1.868
A40: =A39 -> ERIMON | B40: =IF(ISBLANK(A38),"",LEFT(B39,27)&VALUE(RIGHT(B39,1)+1)) -> JKS240702ERIMON_35C_sample_3 | C40: =C39 -> Erica monsoniana | D40: =D39 -> 35C | E40: =IF(ISBLANK(A38),"",E39+1) -> 3 | F40: =F39 -> 45477.656 | G40: 0.61
...

Sheet 20C
A1: GENSPP | B1: ID_Code | C1: Species | D1: Treat | E1: Sample_no | F1: Date_Time | G1: Weight
A2: ERIMON | B2: {=IF(ISBLANK(A2),"",IF(A2="PROREP (L)",VLOOKUP(LEFT($A2,6),'Data Feed (20C)'!$A$1:$G$10,2,FALSE),IF(A2="PROREP (S)", INDEX('Data Feed (20C)'!B:B, MATCH(LEFT($A2,6), 'Data Feed (20C)'!$A$1:$A$10, 0) + 1), VLOOKUP($A2,'Data Feed (20C)'!$A$1:$G$10,2,FALSE))))} -> JKS240702ERIMON_20C_sample_1 | C2: {=IF(ISBLANK(A2),"",IF(A2="PROREP (L)",VLOOKUP(LEFT($A2,6),'Data Feed (20C)'!$A$1:$G$10,3,FALSE),IF(A2="PROREP (S)", INDEX('Data Feed (20C)'!C:C, MATCH(LEFT($A2,6), 'Data Feed (20C)'!$A$1:$A$10, 0) + 1, +1), VLOOKUP($A2,'Data Feed (20C)'!$A$1:$G$10,3,FALSE))))} -> Erica monsoniana | D2: {=IF(ISBLANK(A2),"",IF(A2="PROREP (L)",VLOOKUP(LEFT($A2,6),'Data Feed (20C)'!$A$1:$G$10,4,FALSE),IF(A2="PROREP (S)", INDEX('Data Feed (20C)'!D:D, MATCH(LEFT($A2,6), 'Data Feed (20C)'!$A$1:$A$10, 0) + 1, +1), VLOOKUP($A2,'Data Feed (20C)'!$A$1:$G$10,4,FALSE))))} -> 20C | E2: {=IF(ISBLANK(A2),"",IF(A2="PROREP (L)",VLOOKUP(LEFT($A2,6),'Data Feed (20C)'!$A$1:$G$10,7,FALSE),IF(A2="PROREP (S)", INDEX('Data Feed (20C)'!G:G, MATCH(LEFT($A2,6), 'Data Feed (20C)'!$A$1:$A$10, 0) + 1, +1), VLOOKUP($A2,'Data Feed (20C)'!$A$1:$G$10,7,FALSE))))} -> 1 | F2: 45477.528 | G2: 3.392
A3: =A2 -> ERIMON | B3: =IF(ISBLANK(A2),"",LEFT(B2,27)&VALUE(RIGHT(B2,1)+1)) -> JKS240702ERIMON_20C_sample_2 | C3: =C2 -> Erica monsoniana | D3: =D2 -> 20C | E3: =IF(ISBLANK(A2),"",E2+1) -> 2 | F3: =F2 -> 45477.528 | G3: 2.701
A4: =A3 -> ERIMON | B4: =IF(ISBLANK(A2),"",LEFT(B3,27)&VALUE(RIGHT(B3,1)+1)) -> JKS240702ERIMON_20C_sample_3 | C4: =C3 -> Erica monsoniana | D4: =D3 -> 20C | E4: =IF(ISBLANK(A2),"",E3+1) -> 3 | F4: =F3 -> 45477.528 | G4: 2.777
A5: =A4 -> ERIMON | B5: =IF(ISBLANK(A2),"",LEFT(B4,27)&VALUE(RIGHT(B4,1)+1)) -> JKS240702ERIMON_20C_sample_4 | C5: =C4 -> Erica monsoniana | D5: =D4 -> 20C | E5: =IF(ISBLANK(A2),"",E4+1) -> 4 | F5: =F4 -> 45477.528 | G5: 1.729
A6: =A5 -> ERIMON | B6: =IF(ISBLANK(A2),"",LEFT(B5,27)&VALUE(RIGHT(B5,1)+1)) -> JKS240702ERIMON_20C_sample_5 | C6: =C5 -> Erica monsoniana | D6: =D5 -> 20C | E6: =IF(ISBLANK(A2),"",E5+1) -> 5 | F6: =F5 -> 45477.528 | G6: 2.339
A7: =A6 -> ERIMON | B7: =IF(ISBLANK(A2),"",LEFT(B6,27)&VALUE(RIGHT(B6,1)+1)) -> JKS240702ERIMON_20C_sample_6 | C7: =C6 -> Erica monsoniana | D7: =D6 -> 20C | E7: =IF(ISBLANK(A2),"",E6+1) -> 6 | F7: =F6 -> 45477.528 | G7: 1.124
A8: PROREP (L) | B8: {=IF(ISBLANK(A8),"",IF(A8="PROREP (L)",VLOOKUP(LEFT($A8,6),'Data Feed (20C)'!$A$1:$G$10,2,FALSE),IF(A8="PROREP (S)", INDEX('Data Feed (20C)'!B:B, MATCH(LEFT($A8,6), 'Data Feed (20C)'!$A$1:$A$10, 0) + 1), VLOOKUP($A8,'Data Feed (20C)'!$A$1:$G$10,2,FALSE))))} -> JKL240702PROREP_20C_sample_1 | C8: {=IF(ISBLANK(A8),"",IF(A8="PROREP (L)",VLOOKUP(LEFT($A8,6),'Data Feed (20C)'!$A$1:$G$10,3,FALSE),IF(A8="PROREP (S)", INDEX('Data Feed (20C)'!C:C, MATCH(LEFT($A8,6), 'Data Feed (20C)'!$A$1:$A$10, 0) + 1, +1), VLOOKUP($A8,'Data Feed (20C)'!$A$1:$G$10,3,FALSE))))} -> Protea repens | D8: {=IF(ISBLANK(A8),"",IF(A8="PROREP (L)",VLOOKUP(LEFT($A8,6),'Data Feed (20C)'!$A$1:$G$10,4,FALSE),IF(A8="PROREP (S)", INDEX('Data Feed (20C)'!D:D, MATCH(LEFT($A8,6), 'Data Feed (20C)'!$A$1:$A$10, 0) + 1, +1), VLOOKUP($A8,'Data Feed (20C)'!$A$1:$G$10,4,FALSE))))} -> 20C | E8: {=IF(ISBLANK(A8),"",IF(A8="PROREP (L)",VLOOKUP(LEFT($A8,6),'Data Feed (20C)'!$A$1:$G$10,7,FALSE),IF(A8="PROREP (S)", INDEX('Data Feed (20C)'!G:G, MATCH(LEFT($A8,6), 'Data Feed (20C)'!$A$1:$A$10, 0) + 1, +1), VLOOKUP($A8,'Data Feed (20C)'!$A$1:$G$10,7,FALSE))))} -> 1 | F8: 45477.574 | G8: 0.592
A9: =A8 -> PROREP (L) | B9: =IF(ISBLANK(A8),"",LEFT(B8,27)&VALUE(RIGHT(B8,1)+1)) -> JKL240702PROREP_20C_sample_2 | C9: =C8 -> Protea repens | D9: =D8 -> 20C | E9: =IF(ISBLANK(A8),"",E8+1) -> 2 | F9: =F8 -> 45477.574 | G9: 0.451
A10: =A9 -> PROREP (L) | B10: =IF(ISBLANK(A8),"",LEFT(B9,27)&VALUE(RIGHT(B9,1)+1)) -> JKL240702PROREP_20C_sample_3 | C10: =C9 -> Protea repens | D10: =D9 -> 20C | E10: =IF(ISBLANK(A8),"",E9+1) -> 3 | F10: =F9 -> 45477.574 | G10: 0.683
A11: =A10 -> PROREP (L) | B11: =IF(ISBLANK(A8),"",LEFT(B10,27)&VALUE(RIGHT(B10,1)+1)) -> JKL240702PROREP_20C_sample_4 | C11: =C10 -> Protea repens | D11: =D10 -> 20C | E11: =IF(ISBLANK(A8),"",E10+1) -> 4 | F11: =F10 -> 45477.574 | G11: 0.366
A12: =A11 -> PROREP (L) | B12: =IF(ISBLANK(A8),"",LEFT(B11,27)&VALUE(RIGHT(B11,1)+1)) -> JKL240702PROREP_20C_sample_5 | C12: =C11 -> Protea repens | D12: =D11 -> 20C | E12: =IF(ISBLANK(A8),"",E11+1) -> 5 | F12: =F11 -> 45477.574 | G12: 0.526
A13: =A12 -> PROREP (L) | B13: =IF(ISBLANK(A8),"",LEFT(B12,27)&VALUE(RIGHT(B12,1)+1)) -> JKL240702PROREP_20C_sample_6 | C13: =C12 -> Protea repens | D13: =D12 -> 20C | E13: =IF(ISBLANK(A8),"",E12+1) -> 6 | F13: =F12 -> 45477.574 | G13: 0.442
A14: ERIMON | B14: {=IF(ISBLANK(A14),"",IF(A14="PROREP (L)",VLOOKUP(LEFT($A14,6),'Data Feed (20C)'!$A$1:$G$10,2,FALSE),IF(A14="PROREP (S)", INDEX('Data Feed (20C)'!B:B, MATCH(LEFT($A14,6), 'Data Feed (20C)'!$A$1:$A$10, 0) + 1), VLOOKUP($A14,'Data Feed (20C)'!$A$1:$G$10,2,FALSE))))} -> JKS240702ERIMON_20C_sample_1 | C14: {=IF(ISBLANK(A14),"",IF(A14="PROREP (L)",VLOOKUP(LEFT($A14,6),'Data Feed (20C)'!$A$1:$G$10,3,FALSE),IF(A14="PROREP (S)", INDEX('Data Feed (20C)'!C:C, MATCH(LEFT($A14,6), 'Data Feed (20C)'!$A$1:$A$10, 0) + 1, +1), VLOOKUP($A14,'Data Feed (20C)'!$A$1:$G$10,3,FALSE))))} -> Erica monsoniana | D14: {=IF(ISBLANK(A14),"",IF(A14="PROREP (L)",VLOOKUP(LEFT($A14,6),'Data Feed (20C)'!$A$1:$G$10,4,FALSE),IF(A14="PROREP (S)", INDEX('Data Feed (20C)'!D:D, MATCH(LEFT($A14,6), 'Data Feed (20C)'!$A$1:$A$10, 0) + 1, +1), VLOOKUP($A14,'Data Feed (20C)'!$A$1:$G$10,4,FALSE))))} -> 20C | E14: {=IF(ISBLANK(A14),"",IF(A14="PROREP (L)",VLOOKUP(LEFT($A14,6),'Data Feed (20C)'!$A$1:$G$10,7,FALSE),IF(A14="PROREP (S)", INDEX('Data Feed (20C)'!G:G, MATCH(LEFT($A14,6), 'Data Feed (20C)'!$A$1:$A$10, 0) + 1, +1), VLOOKUP($A14,'Data Feed (20C)'!$A$1:$G$10,7,FALSE))))} -> 1 | F14: 45477.579 | G14: 3.275
A15: =A14 -> ERIMON | B15: =IF(ISBLANK(A14),"",LEFT(B14,27)&VALUE(RIGHT(B14,1)+1)) -> JKS240702ERIMON_20C_sample_2 | C15: =C14 -> Erica monsoniana | D15: =D14 -> 20C | E15: =IF(ISBLANK(A14),"",E14+1) -> 2 | F15: =F14 -> 45477.579 | G15: 2.617
A16: =A15 -> ERIMON | B16: =IF(ISBLANK(A14),"",LEFT(B15,27)&VALUE(RIGHT(B15,1)+1)) -> JKS240702ERIMON_20C_sample_3 | C16: =C15 -> Erica monsoniana | D16: =D15 -> 20C | E16: =IF(ISBLANK(A14),"",E15+1) -> 3 | F16: =F15 -> 45477.579 | G16: 2.631
A17: =A16 -> ERIMON | B17: =IF(ISBLANK(A14),"",LEFT(B16,27)&VALUE(RIGHT(B16,1)+1)) -> JKS240702ERIMON_20C_sample_4 | C17: =C16 -> Erica monsoniana | D17: =D16 -> 20C | E17: =IF(ISBLANK(A14),"",E16+1) -> 4 | F17: =F16 -> 45477.579 | G17: 1.687
A18: =A17 -> ERIMON | B18: =IF(ISBLANK(A14),"",LEFT(B17,27)&VALUE(RIGHT(B17,1)+1)) -> JKS240702ERIMON_20C_sample_5 | C18: =C17 -> Erica monsoniana | D18: =D17 -> 20C | E18: =IF(ISBLANK(A14),"",E17+1) -> 5 | F18: =F17 -> 45477.579 | G18: 2.246
A19: =A18 -> ERIMON | B19: =IF(ISBLANK(A14),"",LEFT(B18,27)&VALUE(RIGHT(B18,1)+1)) -> JKS240702ERIMON_20C_sample_6 | C19: =C18 -> Erica monsoniana | D19: =D18 -> 20C | E19: =IF(ISBLANK(A14),"",E18+1) -> 6 | F19: =F18 -> 45477.579 | G19: 1.07
A20: PROREP (S) | B20: {=IF(ISBLANK(A20),"",IF(A20="PROREP (L)",VLOOKUP(LEFT($A20,6),'Data Feed (20C)'!$A$1:$G$10,2,FALSE),IF(A20="PROREP (S)", INDEX('Data Feed (20C)'!B:B, MATCH(LEFT($A20,6), 'Data Feed (20C)'!$A$1:$A$10, 0) + 1), VLOOKUP($A20,'Data Feed (20C)'!$A$1:$G$10,2,FALSE))))} -> JKS240702PROREP_20C_sample_1 | C20: {=IF(ISBLANK(A20),"",IF(A20="PROREP (L)",VLOOKUP(LEFT($A20,6),'Data Feed (20C)'!$A$1:$G$10,3,FALSE),IF(A20="PROREP (S)", INDEX('Data Feed (20C)'!C:C, MATCH(LEFT($A20,6), 'Data Feed (20C)'!$A$1:$A$10, 0) + 1, +1), VLOOKUP($A20,'Data Feed (20C)'!$A$1:$G$10,3,FALSE))))} -> Protea repens | D20: {=IF(ISBLANK(A20),"",IF(A20="PROREP (L)",VLOOKUP(LEFT($A20,6),'Data Feed (20C)'!$A$1:$G$10,4,FALSE),IF(A20="PROREP (S)", INDEX('Data Feed (20C)'!D:D, MATCH(LEFT($A20,6), 'Data Feed (20C)'!$A$1:$A$10, 0) + 1, +1), VLOOKUP($A20,'Data Feed (20C)'!$A$1:$G$10,4,FALSE))))} -> 20C | E20: {=IF(ISBLANK(A20),"",IF(A20="PROREP (L)",VLOOKUP(LEFT($A20,6),'Data Feed (20C)'!$A$1:$G$10,7,FALSE),IF(A20="PROREP (S)", INDEX('Data Feed (20C)'!G:G, MATCH(LEFT($A20,6), 'Data Feed (20C)'!$A$1:$A$10, 0) + 1, +1), VLOOKUP($A20,'Data Feed (20C)'!$A$1:$G$10,7,FALSE))))} -> 1 | F20: 45477.617 | G20: 3.509
A21: =A20 -> PROREP (S) | B21: =IF(ISBLANK(A20),"",LEFT(B20,27)&VALUE(RIGHT(B20,1)+1)) -> JKS240702PROREP_20C_sample_2 | C21: =C20 -> Protea repens | D21: =D20 -> 20C | E21: =IF(ISBLANK(A20),"",E20+1) -> 2 | F21: =F20 -> 45477.617 | G21: 12.993
A22: =A21 -> PROREP (S) | B22: =IF(ISBLANK(A20),"",LEFT(B21,27)&VALUE(RIGHT(B21,1)+1)) -> JKS240702PROREP_20C_sample_3 | C22: =C21 -> Protea repens | D22: =D21 -> 20C | E22: =IF(ISBLANK(A20),"",E21+1) -> 3 | F22: =F21 -> 45477.617 | G22: 16.564
A23: =A22 -> PROREP (S) | B23: =IF(ISBLANK(A20),"",LEFT(B22,27)&VALUE(RIGHT(B22,1)+1)) -> JKS240702PROREP_20C_sample_4 | C23: =C22 -> Protea repens | D23: =D22 -> 20C | E23: =IF(ISBLANK(A20),"",E22+1) -> 4 | F23: =F22 -> 45477.617 | G23: 7.602
A24: =A23 -> PROREP (S) | B24: =IF(ISBLANK(A20),"",LEFT(B23,27)&VALUE(RIGHT(B23,1)+1)) -> JKS240702PROREP_20C_sample_5 | C24: =C23 -> Protea repens | D24: =D23 -> 20C | E24: =IF(ISBLANK(A20),"",E23+1) -> 5 | F24: =F23 -> 45477.617 | G24: 7.244
A25: =A24 -> PROREP (S) | B25: =IF(ISBLANK(A20),"",LEFT(B24,27)&VALUE(RIGHT(B24,1)+1)) -> JKS240702PROREP_20C_sample_6 | C25: =C24 -> Protea repens | D25: =D24 -> 20C | E25: =IF(ISBLANK(A20),"",E24+1) -> 6 | F25: =F24 -> 45477.617 | G25: 26.938
A26: ERIMON | B26: {=IF(ISBLANK(A26),"",IF(A26="PROREP (L)",VLOOKUP(LEFT($A26,6),'Data Feed (20C)'!$A$1:$G$10,2,FALSE),IF(A26="PROREP (S)", INDEX('Data Feed (20C)'!B:B, MATCH(LEFT($A26,6), 'Data Feed (20C)'!$A$1:$A$10, 0) + 1), VLOOKUP($A26,'Data Feed (20C)'!$A$1:$G$10,2,FALSE))))} -> JKS240702ERIMON_20C_sample_1 | C26: {=IF(ISBLANK(A26),"",IF(A26="PROREP (L)",VLOOKUP(LEFT($A26,6),'Data Feed (20C)'!$A$1:$G$10,3,FALSE),IF(A26="PROREP (S)", INDEX('Data Feed (20C)'!C:C, MATCH(LEFT($A26,6), 'Data Feed (20C)'!$A$1:$A$10, 0) + 1, +1), VLOOKUP($A26,'Data Feed (20C)'!$A$1:$G$10,3,FALSE))))} -> Erica monsoniana | D26: {=IF(ISBLANK(A26),"",IF(A26="PROREP (L)",VLOOKUP(LEFT($A26,6),'Data Feed (20C)'!$A$1:$G$10,4,FALSE),IF(A26="PROREP (S)", INDEX('Data Feed (20C)'!D:D, MATCH(LEFT($A26,6), 'Data Feed (20C)'!$A$1:$A$10, 0) + 1, +1), VLOOKUP($A26,'Data Feed (20C)'!$A$1:$G$10,4,FALSE))))} -> 20C | E26: {=IF(ISBLANK(A26),"",IF(A26="PROREP (L)",VLOOKUP(LEFT($A26,6),'Data Feed (20C)'!$A$1:$G$10,7,FALSE),IF(A26="PROREP (S)", INDEX('Data Feed (20C)'!G:G, MATCH(LEFT($A26,6), 'Data Feed (20C)'!$A$1:$A$10, 0) + 1, +1), VLOOKUP($A26,'Data Feed (20C)'!$A$1:$G$10,7,FALSE))))} -> 1 | F26: 45477.619 | G26: 3.2
A27: =A26 -> ERIMON | B27: =IF(ISBLANK(A26),"",LEFT(B26,27)&VALUE(RIGHT(B26,1)+1)) -> JKS240702ERIMON_20C_sample_2 | C27: =C26 -> Erica monsoniana | D27: =D26 -> 20C | E27: =IF(ISBLANK(A26),"",E26+1) -> 2 | F27: =F26 -> 45477.619 | G27: 2.578
A28: =A27 -> ERIMON | B28: =IF(ISBLANK(A26),"",LEFT(B27,27)&VALUE(RIGHT(B27,1)+1)) -> JKS240702ERIMON_20C_sample_3 | C28: =C27 -> Erica monsoniana | D28: =D27 -> 20C | E28: =IF(ISBLANK(A26),"",E27+1) -> 3 | F28: =F27 -> 45477.619 | G28: 2.555
A29: =A28 -> ERIMON | B29: =IF(ISBLANK(A26),"",LEFT(B28,27)&VALUE(RIGHT(B28,1)+1)) -> JKS240702ERIMON_20C_sample_4 | C29: =C28 -> Erica monsoniana | D29: =D28 -> 20C | E29: =IF(ISBLANK(A26),"",E28+1) -> 4 | F29: =F28 -> 45477.619 | G29: 1.648
A30: =A29 -> ERIMON | B30: =IF(ISBLANK(A26),"",LEFT(B29,27)&VALUE(RIGHT(B29,1)+1)) -> JKS240702ERIMON_20C_sample_5 | C30: =C29 -> Erica monsoniana | D30: =D29 -> 20C | E30: =IF(ISBLANK(A26),"",E29+1) -> 5 | F30: =F29 -> 45477.619 | G30: 2.204
A31: =A30 -> ERIMON | B31: =IF(ISBLANK(A26),"",LEFT(B30,27)&VALUE(RIGHT(B30,1)+1)) -> JKS240702ERIMON_20C_sample_6 | C31: =C30 -> Erica monsoniana | D31: =D30 -> 20C | E31: =IF(ISBLANK(A26),"",E30+1) -> 6 | F31: =F30 -> 45477.619 | G31: 1.051
A32: PROREP (L) | B32: {=IF(ISBLANK(A32),"",IF(A32="PROREP (L)",VLOOKUP(LEFT($A32,6),'Data Feed (20C)'!$A$1:$G$10,2,FALSE),IF(A32="PROREP (S)", INDEX('Data Feed (20C)'!B:B, MATCH(LEFT($A32,6), 'Data Feed (20C)'!$A$1:$A$10, 0) + 1), VLOOKUP($A32,'Data Feed (20C)'!$A$1:$G$10,2,FALSE))))} -> JKL240702PROREP_20C_sample_1 | C32: {=IF(ISBLANK(A32),"",IF(A32="PROREP (L)",VLOOKUP(LEFT($A32,6),'Data Feed (20C)'!$A$1:$G$10,3,FALSE),IF(A32="PROREP (S)", INDEX('Data Feed (20C)'!C:C, MATCH(LEFT($A32,6), 'Data Feed (20C)'!$A$1:$A$10, 0) + 1, +1), VLOOKUP($A32,'Data Feed (20C)'!$A$1:$G$10,3,FALSE))))} -> Protea repens | D32: {=IF(ISBLANK(A32),"",IF(A32="PROREP (L)",VLOOKUP(LEFT($A32,6),'Data Feed (20C)'!$A$1:$G$10,4,FALSE),IF(A32="PROREP (S)", INDEX('Data Feed (20C)'!D:D, MATCH(LEFT($A32,6), 'Data Feed (20C)'!$A$1:$A$10, 0) + 1, +1), VLOOKUP($A32,'Data Feed (20C)'!$A$1:$G$10,4,FALSE))))} -> 20C | E32: {=IF(ISBLANK(A32),"",IF(A32="PROREP (L)",VLOOKUP(LEFT($A32,6),'Data Feed (20C)'!$A$1:$G$10,7,FALSE),IF(A32="PROREP (S)", INDEX('Data Feed (20C)'!G:G, MATCH(LEFT($A32,6), 'Data Feed (20C)'!$A$1:$A$10, 0) + 1, +1), VLOOKUP($A32,'Data Feed (20C)'!$A$1:$G$10,7,FALSE))))} -> 1 | F32: 45477.622 | G32: 0.589
A33: =A32 -> PROREP (L) | B33: =IF(ISBLANK(A32),"",LEFT(B32,27)&VALUE(RIGHT(B32,1)+1)) -> JKL240702PROREP_20C_sample_2 | C33: =C32 -> Protea repens | D33: =D32 -> 20C | E33: =IF(ISBLANK(A32),"",E32+1) -> 2 | F33: =F32 -> 45477.622 | G33: 0.449
A34: =A33 -> PROREP (L) | B34: =IF(ISBLANK(A32),"",LEFT(B33,27)&VALUE(RIGHT(B33,1)+1)) -> JKL240702PROREP_20C_sample_3 | C34: =C33 -> Protea repens | D34: =D33 -> 20C | E34: =IF(ISBLANK(A32),"",E33+1) -> 3 | F34: =F33 -> 45477.622 | G34: 0.674
A35: =A34 -> PROREP (L) | B35: =IF(ISBLANK(A32),"",LEFT(B34,27)&VALUE(RIGHT(B34,1)+1)) -> JKL240702PROREP_20C_sample_4 | C35: =C34 -> Protea repens | D35: =D34 -> 20C | E35: =IF(ISBLANK(A32),"",E34+1) -> 4 | F35: =F34 -> 45477.622 | G35: 0.36
A36: =A35 -> PROREP (L) | B36: =IF(ISBLANK(A32),"",LEFT(B35,27)&VALUE(RIGHT(B35,1)+1)) -> JKL240702PROREP_20C_sample_5 | C36: =C35 -> Protea repens | D36: =D35 -> 20C | E36: =IF(ISBLANK(A32),"",E35+1) -> 5 | F36: =F35 -> 45477.622 | G36: 0.515
A37: =A36 -> PROREP (L) | B37: =IF(ISBLANK(A32),"",LEFT(B36,27)&VALUE(RIGHT(B36,1)+1)) -> JKL240702PROREP_20C_sample_6 | C37: =C36 -> Protea repens | D37: =D36 -> 20C | E37: =IF(ISBLANK(A32),"",E36+1) -> 6 | F37: =F36 -> 45477.622 | G37: 0.431
A38: ERIMON | B38: {=IF(ISBLANK(A38),"",IF(A38="PROREP (L)",VLOOKUP(LEFT($A38,6),'Data Feed (20C)'!$A$1:$G$10,2,FALSE),IF(A38="PROREP (S)", INDEX('Data Feed (20C)'!B:B, MATCH(LEFT($A38,6), 'Data Feed (20C)'!$A$1:$A$10, 0) + 1), VLOOKUP($A38,'Data Feed (20C)'!$A$1:$G$10,2,FALSE))))} -> JKS240702ERIMON_20C_sample_1 | C38: {=IF(ISBLANK(A38),"",IF(A38="PROREP (L)",VLOOKUP(LEFT($A38,6),'Data Feed (20C)'!$A$1:$G$10,3,FALSE),IF(A38="PROREP (S)", INDEX('Data Feed (20C)'!C:C, MATCH(LEFT($A38,6), 'Data Feed (20C)'!$A$1:$A$10, 0) + 1, +1), VLOOKUP($A38,'Data Feed (20C)'!$A$1:$G$10,3,FALSE))))} -> Erica monsoniana | D38: {=IF(ISBLANK(A38),"",IF(A38="PROREP (L)",VLOOKUP(LEFT($A38,6),'Data Feed (20C)'!$A$1:$G$10,4,FALSE),IF(A38="PROREP (S)", INDEX('Data Feed (20C)'!D:D, MATCH(LEFT($A38,6), 'Data Feed (20C)'!$A$1:$A$10, 0) + 1, +1), VLOOKUP($A38,'Data Feed (20C)'!$A$1:$G$10,4,FALSE))))} -> 20C | E38: {=IF(ISBLANK(A38),"",IF(A38="PROREP (L)",VLOOKUP(LEFT($A38,6),'Data Feed (20C)'!$A$1:$G$10,7,FALSE),IF(A38="PROREP (S)", INDEX('Data Feed (20C)'!G:G, MATCH(LEFT($A38,6), 'Data Feed (20C)'!$A$1:$A$10, 0) + 1, +1), VLOOKUP($A38,'Data Feed (20C)'!$A$1:$G$10,7,FALSE))))} -> 1 | F38: 45477.665 | G38: 3.124
A39: =A38 -> ERIMON | B39: =IF(ISBLANK(A38),"",LEFT(B38,27)&VALUE(RIGHT(B38,1)+1)) -> JKS240702ERIMON_20C_sample_2 | C39: =C38 -> Erica monsoniana | D39: =D38 -> 20C | E39: =IF(ISBLANK(A38),"",E38+1) -> 2 | F39: =F38 -> 45477.665 | G39: 2.539
A40: =A39 -> ERIMON | B40: =IF(ISBLANK(A38),"",LEFT(B39,27)&VALUE(RIGHT(B39,1)+1)) -> JKS240702ERIMON_20C_sample_3 | C40: =C39 -> Erica monsoniana | D40: =D39 -> 20C | E40: =IF(ISBLANK(A38),"",E39+1) -> 3 | F40: =F39 -> 45477.665 | G40: 2.496
...

Sheet 25C
A1: GENSPP | B1: ID_Code | C1: Species | D1: Treat | E1: Sample_no | F1: Date_Time | G1: Weight
A2: ERIMON | B2: {=IF(ISBLANK(A2),"",IF(A2="PROREP (L)",VLOOKUP(LEFT($A2,6),'Data Feed (25C)'!$A$1:$G$10,2,FALSE),IF(A2="PROREP (S)", INDEX('Data Feed (25C)'!B:B, MATCH(LEFT($A2,6), 'Data Feed (25C)'!$A$1:$A$10, 0) + 1), VLOOKUP($A2,'Data Feed (25C)'!$A$1:$G$10,2,FALSE))))} -> JKS240702ERIMON_25C_sample_1 | C2: {=IF(ISBLANK(A2),"",IF(A2="PROREP (L)",VLOOKUP(LEFT($A2,6),'Data Feed (25C)'!$A$1:$G$10,3,FALSE),IF(A2="PROREP (S)", INDEX('Data Feed (25C)'!C:C, MATCH(LEFT($A2,6), 'Data Feed (25C)'!$A$1:$A$10, 0) + 1, +1), VLOOKUP($A2,'Data Feed (25C)'!$A$1:$G$10,3,FALSE))))} -> Erica monsoniana | D2: {=IF(ISBLANK(A2),"",IF(A2="PROREP (L)",VLOOKUP(LEFT($A2,6),'Data Feed (25C)'!$A$1:$G$10,4,FALSE),IF(A2="PROREP (S)", INDEX('Data Feed (25C)'!D:D, MATCH(LEFT($A2,6), 'Data Feed (25C)'!$A$1:$A$10, 0) + 1, +1), VLOOKUP($A2,'Data Feed (25C)'!$A$1:$G$10,4,FALSE))))} -> 25C | E2: {=IF(ISBLANK(A2),"",IF(A2="PROREP (L)",VLOOKUP(LEFT($A2,6),'Data Feed (25C)'!$A$1:$G$10,7,FALSE),IF(A2="PROREP (S)", INDEX('Data Feed (25C)'!G:G, MATCH(LEFT($A2,6), 'Data Feed (25C)'!$A$1:$A$10, 0) + 1, +1), VLOOKUP($A2,'Data Feed (25C)'!$A$1:$G$10,7,FALSE))))} -> 1 | F2: 45477.525 | G2: 1.13
A3: =A2 -> ERIMON | B3: =IF(ISBLANK(A2),"",LEFT(B2,27)&VALUE(RIGHT(B2,1)+1)) -> JKS240702ERIMON_25C_sample_2 | C3: =C2 -> Erica monsoniana | D3: =D2 -> 25C | E3: =IF(ISBLANK(A2),"",E2+1) -> 2 | F3: =F2 -> 45477.525
A4: =A3 -> ERIMON | B4: =IF(ISBLANK(A2),"",LEFT(B3,27)&VALUE(RIGHT(B3,1)+1)) -> JKS240702ERIMON_25C_sample_3 | C4: =C3 -> Erica monsoniana | D4: =D3 -> 25C | E4: =IF(ISBLANK(A2),"",E3+1) -> 3 | F4: =F3 -> 45477.525 | G4: 1.56
A5: =A4 -> ERIMON | B5: =IF(ISBLANK(A2),"",LEFT(B4,27)&VALUE(RIGHT(B4,1)+1)) -> JKS240702ERIMON_25C_sample_4 | C5: =C4 -> Erica monsoniana | D5: =D4 -> 25C | E5: =IF(ISBLANK(A2),"",E4+1) -> 4 | F5: =F4 -> 45477.525 | G5: 3.06
A6: =A5 -> ERIMON | B6: =IF(ISBLANK(A2),"",LEFT(B5,27)&VALUE(RIGHT(B5,1)+1)) -> JKS240702ERIMON_25C_sample_5 | C6: =C5 -> Erica monsoniana | D6: =D5 -> 25C | E6: =IF(ISBLANK(A2),"",E5+1) -> 5 | F6: =F5 -> 45477.525 | G6: 2.25
A7: =A6 -> ERIMON | B7: =IF(ISBLANK(A2),"",LEFT(B6,27)&VALUE(RIGHT(B6,1)+1)) -> JKS240702ERIMON_25C_sample_6 | C7: =C6 -> Erica monsoniana | D7: =D6 -> 25C | E7: =IF(ISBLANK(A2),"",E6+1) -> 6 | F7: =F6 -> 45477.525
A8: PROREP (L) | B8: {=IF(ISBLANK(A8),"",IF(A8="PROREP (L)",VLOOKUP(LEFT($A8,6),'Data Feed (25C)'!$A$1:$G$10,2,FALSE),IF(A8="PROREP (S)", INDEX('Data Feed (25C)'!B:B, MATCH(LEFT($A8,6), 'Data Feed (25C)'!$A$1:$A$10, 0) + 1), VLOOKUP($A8,'Data Feed (25C)'!$A$1:$G$10,2,FALSE))))} -> JKL240702PROREP_25C_sample_1 | C8: {=IF(ISBLANK(A8),"",IF(A8="PROREP (L)",VLOOKUP(LEFT($A8,6),'Data Feed (25C)'!$A$1:$G$10,3,FALSE),IF(A8="PROREP (S)", INDEX('Data Feed (25C)'!C:C, MATCH(LEFT($A8,6), 'Data Feed (25C)'!$A$1:$A$10, 0) + 1, +1), VLOOKUP($A8,'Data Feed (25C)'!$A$1:$G$10,3,FALSE))))} -> Protea repens | D8: {=IF(ISBLANK(A8),"",IF(A8="PROREP (L)",VLOOKUP(LEFT($A8,6),'Data Feed (25C)'!$A$1:$G$10,4,FALSE),IF(A8="PROREP (S)", INDEX('Data Feed (25C)'!D:D, MATCH(LEFT($A8,6), 'Data Feed (25C)'!$A$1:$A$10, 0) + 1, +1), VLOOKUP($A8,'Data Feed (25C)'!$A$1:$G$10,4,FALSE))))} -> 25C | E8: {=IF(ISBLANK(A8),"",IF(A8="PROREP (L)",VLOOKUP(LEFT($A8,6),'Data Feed (25C)'!$A$1:$G$10,7,FALSE),IF(A8="PROREP (S)", INDEX('Data Feed (25C)'!G:G, MATCH(LEFT($A8,6), 'Data Feed (25C)'!$A$1:$A$10, 0) + 1, +1), VLOOKUP($A8,'Data Feed (25C)'!$A$1:$G$10,7,FALSE))))} -> 1 | F8: 45477.575 | G8: 0.41
A9: =A8 -> PROREP (L) | B9: =IF(ISBLANK(A8),"",LEFT(B8,27)&VALUE(RIGHT(B8,1)+1)) -> JKL240702PROREP_25C_sample_2 | C9: =C8 -> Protea repens | D9: =D8 -> 25C | E9: =IF(ISBLANK(A8),"",E8+1) -> 2 | F9: =F8 -> 45477.575 | G9: 0.56
A10: =A9 -> PROREP (L) | B10: =IF(ISBLANK(A8),"",LEFT(B9,27)&VALUE(RIGHT(B9,1)+1)) -> JKL240702PROREP_25C_sample_3 | C10: =C9 -> Protea repens | D10: =D9 -> 25C | E10: =IF(ISBLANK(A8),"",E9+1) -> 3 | F10: =F9 -> 45477.575 | G10: 0.7
A11: =A10 -> PROREP (L) | B11: =IF(ISBLANK(A8),"",LEFT(B10,27)&VALUE(RIGHT(B10,1)+1)) -> JKL240702PROREP_25C_sample_4 | C11: =C10 -> Protea repens | D11: =D10 -> 25C | E11: =IF(ISBLANK(A8),"",E10+1) -> 4 | F11: =F10 -> 45477.575 | G11: 0.49
A12: =A11 -> PROREP (L) | B12: =IF(ISBLANK(A8),"",LEFT(B11,27)&VALUE(RIGHT(B11,1)+1)) -> JKL240702PROREP_25C_sample_5 | C12: =C11 -> Protea repens | D12: =D11 -> 25C | E12: =IF(ISBLANK(A8),"",E11+1) -> 5 | F12: =F11 -> 45477.575 | G12: 0.48
A13: =A12 -> PROREP (L) | B13: =IF(ISBLANK(A8),"",LEFT(B12,27)&VALUE(RIGHT(B12,1)+1)) -> JKL240702PROREP_25C_sample_6 | C13: =C12 -> Protea repens | D13: =D12 -> 25C | E13: =IF(ISBLANK(A8),"",E12+1) -> 6 | F13: =F12 -> 45477.575 | G13: 0.57
A14: ERIMON | B14: {=IF(ISBLANK(A14),"",IF(A14="PROREP (L)",VLOOKUP(LEFT($A14,6),'Data Feed (25C)'!$A$1:$G$10,2,FALSE),IF(A14="PROREP (S)", INDEX('Data Feed (25C)'!B:B, MATCH(LEFT($A14,6), 'Data Feed (25C)'!$A$1:$A$10, 0) + 1), VLOOKUP($A14,'Data Feed (25C)'!$A$1:$G$10,2,FALSE))))} -> JKS240702ERIMON_25C_sample_1 | C14: {=IF(ISBLANK(A14),"",IF(A14="PROREP (L)",VLOOKUP(LEFT($A14,6),'Data Feed (25C)'!$A$1:$G$10,3,FALSE),IF(A14="PROREP (S)", INDEX('Data Feed (25C)'!C:C, MATCH(LEFT($A14,6), 'Data Feed (25C)'!$A$1:$A$10, 0) + 1, +1), VLOOKUP($A14,'Data Feed (25C)'!$A$1:$G$10,3,FALSE))))} -> Erica monsoniana | D14: {=IF(ISBLANK(A14),"",IF(A14="PROREP (L)",VLOOKUP(LEFT($A14,6),'Data Feed (25C)'!$A$1:$G$10,4,FALSE),IF(A14="PROREP (S)", INDEX('Data Feed (25C)'!D:D, MATCH(LEFT($A14,6), 'Data Feed (25C)'!$A$1:$A$10, 0) + 1, +1), VLOOKUP($A14,'Data Feed (25C)'!$A$1:$G$10,4,FALSE))))} -> 25C | E14: {=IF(ISBLANK(A14),"",IF(A14="PROREP (L)",VLOOKUP(LEFT($A14,6),'Data Feed (25C)'!$A$1:$G$10,7,FALSE),IF(A14="PROREP (S)", INDEX('Data Feed (25C)'!G:G, MATCH(LEFT($A14,6), 'Data Feed (25C)'!$A$1:$A$10, 0) + 1, +1), VLOOKUP($A14,'Data Feed (25C)'!$A$1:$G$10,7,FALSE))))} -> 1 | F14: 45477.576 | G14: 1.03
A15: =A14 -> ERIMON | B15: =IF(ISBLANK(A14),"",LEFT(B14,27)&VALUE(RIGHT(B14,1)+1)) -> JKS240702ERIMON_25C_sample_2 | C15: =C14 -> Erica monsoniana | D15: =D14 -> 25C | E15: =IF(ISBLANK(A14),"",E14+1) -> 2 | F15: =F14 -> 45477.576
A16: =A15 -> ERIMON | B16: =IF(ISBLANK(A14),"",LEFT(B15,27)&VALUE(RIGHT(B15,1)+1)) -> JKS240702ERIMON_25C_sample_3 | C16: =C15 -> Erica monsoniana | D16: =D15 -> 25C | E16: =IF(ISBLANK(A14),"",E15+1) -> 3 | F16: =F15 -> 45477.576 | G16: 1.46
A17: =A16 -> ERIMON | B17: =IF(ISBLANK(A14),"",LEFT(B16,27)&VALUE(RIGHT(B16,1)+1)) -> JKS240702ERIMON_25C_sample_4 | C17: =C16 -> Erica monsoniana | D17: =D16 -> 25C | E17: =IF(ISBLANK(A14),"",E16+1) -> 4 | F17: =F16 -> 45477.576 | G17: 2.91
A18: =A17 -> ERIMON | B18: =IF(ISBLANK(A14),"",LEFT(B17,27)&VALUE(RIGHT(B17,1)+1)) -> JKS240702ERIMON_25C_sample_5 | C18: =C17 -> Erica monsoniana | D18: =D17 -> 25C | E18: =IF(ISBLANK(A14),"",E17+1) -> 5 | F18: =F17 -> 45477.576 | G18: 2.1
A19: =A18 -> ERIMON | B19: =IF(ISBLANK(A14),"",LEFT(B18,27)&VALUE(RIGHT(B18,1)+1)) -> JKS240702ERIMON_25C_sample_6 | C19: =C18 -> Erica monsoniana | D19: =D18 -> 25C | E19: =IF(ISBLANK(A14),"",E18+1) -> 6 | F19: =F18 -> 45477.576
A20: PROREP (S) | B20: {=IF(ISBLANK(A20),"",IF(A20="PROREP (L)",VLOOKUP(LEFT($A20,6),'Data Feed (25C)'!$A$1:$G$10,2,FALSE),IF(A20="PROREP (S)", INDEX('Data Feed (25C)'!B:B, MATCH(LEFT($A20,6), 'Data Feed (25C)'!$A$1:$A$10, 0) + 1), VLOOKUP($A20,'Data Feed (25C)'!$A$1:$G$10,2,FALSE))))} -> JKS240702PROREP_25C_sample_1 | C20: {=IF(ISBLANK(A20),"",IF(A20="PROREP (L)",VLOOKUP(LEFT($A20,6),'Data Feed (25C)'!$A$1:$G$10,3,FALSE),IF(A20="PROREP (S)", INDEX('Data Feed (25C)'!C:C, MATCH(LEFT($A20,6), 'Data Feed (25C)'!$A$1:$A$10, 0) + 1, +1), VLOOKUP($A20,'Data Feed (25C)'!$A$1:$G$10,3,FALSE))))} -> Protea repens | D20: {=IF(ISBLANK(A20),"",IF(A20="PROREP (L)",VLOOKUP(LEFT($A20,6),'Data Feed (25C)'!$A$1:$G$10,4,FALSE),IF(A20="PROREP (S)", INDEX('Data Feed (25C)'!D:D, MATCH(LEFT($A20,6), 'Data Feed (25C)'!$A$1:$A$10, 0) + 1, +1), VLOOKUP($A20,'Data Feed (25C)'!$A$1:$G$10,4,FALSE))))} -> 25C | E20: {=IF(ISBLANK(A20),"",IF(A20="PROREP (L)",VLOOKUP(LEFT($A20,6),'Data Feed (25C)'!$A$1:$G$10,7,FALSE),IF(A20="PROREP (S)", INDEX('Data Feed (25C)'!G:G, MATCH(LEFT($A20,6), 'Data Feed (25C)'!$A$1:$A$10, 0) + 1, +1), VLOOKUP($A20,'Data Feed (25C)'!$A$1:$G$10,7,FALSE))))} -> 1 | F20: 45477.616 | G20: 12.29
A21: =A20 -> PROREP (S) | B21: =IF(ISBLANK(A20),"",LEFT(B20,27)&VALUE(RIGHT(B20,1)+1)) -> JKS240702PROREP_25C_sample_2 | C21: =C20 -> Protea repens | D21: =D20 -> 25C | E21: =IF(ISBLANK(A20),"",E20+1) -> 2 | F21: =F20 -> 45477.616 | G21: 9.9
A22: =A21 -> PROREP (S) | B22: =IF(ISBLANK(A20),"",LEFT(B21,27)&VALUE(RIGHT(B21,1)+1)) -> JKS240702PROREP_25C_sample_3 | C22: =C21 -> Protea repens | D22: =D21 -> 25C | E22: =IF(ISBLANK(A20),"",E21+1) -> 3 | F22: =F21 -> 45477.616
A23: =A22 -> PROREP (S) | B23: =IF(ISBLANK(A20),"",LEFT(B22,27)&VALUE(RIGHT(B22,1)+1)) -> JKS240702PROREP_25C_sample_4 | C23: =C22 -> Protea repens | D23: =D22 -> 25C | E23: =IF(ISBLANK(A20),"",E22+1) -> 4 | F23: =F22 -> 45477.616 | G23: 2.74
A24: =A23 -> PROREP (S) | B24: =IF(ISBLANK(A20),"",LEFT(B23,27)&VALUE(RIGHT(B23,1)+1)) -> JKS240702PROREP_25C_sample_5 | C24: =C23 -> Protea repens | D24: =D23 -> 25C | E24: =IF(ISBLANK(A20),"",E23+1) -> 5 | F24: =F23 -> 45477.616
A25: =A24 -> PROREP (S) | B25: =IF(ISBLANK(A20),"",LEFT(B24,27)&VALUE(RIGHT(B24,1)+1)) -> JKS240702PROREP_25C_sample_6 | C25: =C24 -> Protea repens | D25: =D24 -> 25C | E25: =IF(ISBLANK(A20),"",E24+1) -> 6 | F25: =F24 -> 45477.616 | G25: 5.01
A26: ERIMON | B26: {=IF(ISBLANK(A26),"",IF(A26="PROREP (L)",VLOOKUP(LEFT($A26,6),'Data Feed (25C)'!$A$1:$G$10,2,FALSE),IF(A26="PROREP (S)", INDEX('Data Feed (25C)'!B:B, MATCH(LEFT($A26,6), 'Data Feed (25C)'!$A$1:$A$10, 0) + 1), VLOOKUP($A26,'Data Feed (25C)'!$A$1:$G$10,2,FALSE))))} -> JKS240702ERIMON_25C_sample_1 | C26: {=IF(ISBLANK(A26),"",IF(A26="PROREP (L)",VLOOKUP(LEFT($A26,6),'Data Feed (25C)'!$A$1:$G$10,3,FALSE),IF(A26="PROREP (S)", INDEX('Data Feed (25C)'!C:C, MATCH(LEFT($A26,6), 'Data Feed (25C)'!$A$1:$A$10, 0) + 1, +1), VLOOKUP($A26,'Data Feed (25C)'!$A$1:$G$10,3,FALSE))))} -> Erica monsoniana | D26: {=IF(ISBLANK(A26),"",IF(A26="PROREP (L)",VLOOKUP(LEFT($A26,6),'Data Feed (25C)'!$A$1:$G$10,4,FALSE),IF(A26="PROREP (S)", INDEX('Data Feed (25C)'!D:D, MATCH(LEFT($A26,6), 'Data Feed (25C)'!$A$1:$A$10, 0) + 1, +1), VLOOKUP($A26,'Data Feed (25C)'!$A$1:$G$10,4,FALSE))))} -> 25C | E26: {=IF(ISBLANK(A26),"",IF(A26="PROREP (L)",VLOOKUP(LEFT($A26,6),'Data Feed (25C)'!$A$1:$G$10,7,FALSE),IF(A26="PROREP (S)", INDEX('Data Feed (25C)'!G:G, MATCH(LEFT($A26,6), 'Data Feed (25C)'!$A$1:$A$10, 0) + 1, +1), VLOOKUP($A26,'Data Feed (25C)'!$A$1:$G$10,7,FALSE))))} -> 1 | F26: 45477.618 | G26: 1.01
A27: =A26 -> ERIMON | B27: =IF(ISBLANK(A26),"",LEFT(B26,27)&VALUE(RIGHT(B26,1)+1)) -> JKS240702ERIMON_25C_sample_2 | C27: =C26 -> Erica monsoniana | D27: =D26 -> 25C | E27: =IF(ISBLANK(A26),"",E26+1) -> 2 | F27: =F26 -> 45477.618
A28: =A27 -> ERIMON | B28: =IF(ISBLANK(A26),"",LEFT(B27,27)&VALUE(RIGHT(B27,1)+1)) -> JKS240702ERIMON_25C_sample_3 | C28: =C27 -> Erica monsoniana | D28: =D27 -> 25C | E28: =IF(ISBLANK(A26),"",E27+1) -> 3 | F28: =F27 -> 45477.618 | G28: 1.42
A29: =A28 -> ERIMON | B29: =IF(ISBLANK(A26),"",LEFT(B28,27)&VALUE(RIGHT(B28,1)+1)) -> JKS240702ERIMON_25C_sample_4 | C29: =C28 -> Erica monsoniana | D29: =D28 -> 25C | E29: =IF(ISBLANK(A26),"",E28+1) -> 4 | F29: =F28 -> 45477.618 | G29: 2.82
