Workbook

Sheet 20C
A1: GENSPP | B1: ID_Code | C1: Species | D1: Treat | E1: Sample_no | F1: Date_Time | G1: Weight
A2: PASOBT | B2: =IF(ISBLANK(A2),"",VLOOKUP($A2,'Data Feed (20C)'!$A$1:$G$14,2,FALSE)) -> DKR250911PASOBT_20C_sample_1 | C2: =IF(ISBLANK(A2),"",VLOOKUP($A2,'Data Feed (20C)'!$A$1:$G$14,3,FALSE)) -> Passerina obtusifolia | D2: =IF(ISBLANK(A2),"",VLOOKUP($A2,'Data Feed (20C)'!$A$1:$G$14,4,FALSE)) -> 20C | E2: =IF(ISBLANK(A2),"",VLOOKUP($A2,'Data Feed (20C)'!$A$1:$G$14,7,FALSE)) -> 1 | F2: 45912.424 | G2: 3.416
A3: =A2 -> PASOBT | B3: =IF(ISBLANK(A2),"",LEFT(B2,27)&VALUE(RIGHT(B2,1)+1)) -> DKR250911PASOBT_20C_sample_2 | C3: =C2 -> Passerina obtusifolia | D3: =D2 -> 20C | E3: =IF(ISBLANK(A2),"",E2+1) -> 2 | F3: =F2 -> 45912.424 | G3: 4.734
A4: =A3 -> PASOBT | B4: =IF(ISBLANK(A2),"",LEFT(B3,27)&VALUE(RIGHT(B3,1)+1)) -> DKR250911PASOBT_20C_sample_3 | C4: =C3 -> Passerina obtusifolia | D4: =D3 -> 20C | E4: =IF(ISBLANK(A2),"",E3+1) -> 3 | F4: =F3 -> 45912.424 | G4: 1.663
A5: =A4 -> PASOBT | B5: =IF(ISBLANK(A2),"",LEFT(B4,27)&VALUE(RIGHT(B4,1)+1)) -> DKR250911PASOBT_20C_sample_4 | C5: =C4 -> Passerina obtusifolia | D5: =D4 -> 20C | E5: =IF(ISBLANK(A2),"",E4+1) -> 4 | F5: =F4 -> 45912.424 | G5: 2.569
A6: =A5 -> PASOBT | B6: =IF(ISBLANK(A2),"",LEFT(B5,27)&VALUE(RIGHT(B5,1)+1)) -> DKR250911PASOBT_20C_sample_5 | C6: =C5 -> Passerina obtusifolia | D6: =D5 -> 20C | E6: =IF(ISBLANK(A2),"",E5+1) -> 5 | F6: =F5 -> 45912.424 | G6: 1.956
A7: =A6 -> PASOBT | B7: =IF(ISBLANK(A2),"",LEFT(B6,27)&VALUE(RIGHT(B6,1)+1)) -> DKR250911PASOBT_20C_sample_6 | C7: =C6 -> Passerina obtusifolia | D7: =D6 -> 20C | E7: =IF(ISBLANK(A2),"",E6+1) -> 6 | F7: =F6 -> 45912.424 | G7: 3.581
A8: PROLOR | B8: =IF(ISBLANK(A8),"",VLOOKUP($A8,'Data Feed (20C)'!$A$1:$G$14,2,FALSE)) -> DKF250911PROLOR_20C_sample_1 | C8: =IF(ISBLANK(A8),"",VLOOKUP($A8,'Data Feed (20C)'!$A$1:$G$14,3,FALSE)) -> Protea lorifolia | D8: =IF(ISBLANK(A8),"",VLOOKUP($A8,'Data Feed (20C)'!$A$1:$G$14,4,FALSE)) -> 20C | E8: =IF(ISBLANK(A8),"",VLOOKUP($A8,'Data Feed (20C)'!$A$1:$G$14,7,FALSE)) -> 1 | F8: 45912.426 | G8: 3.35
A9: =A8 -> PROLOR | B9: =IF(ISBLANK(A8),"",LEFT(B8,27)&VALUE(RIGHT(B8,1)+1)) -> DKF250911PROLOR_20C_sample_2 | C9: =C8 -> Protea lorifolia | D9: =D8 -> 20C | E9: =IF(ISBLANK(A8),"",E8+1) -> 2 | F9: =F8 -> 45912.426 | G9: 3.796
A10: =A9 -> PROLOR | B10: =IF(ISBLANK(A8),"",LEFT(B9,27)&VALUE(RIGHT(B9,1)+1)) -> DKF250911PROLOR_20C_sample_3 | C10: =C9 -> Protea lorifolia | D10: =D9 -> 20C | E10: =IF(ISBLANK(A8),"",E9+1) -> 3 | F10: =F9 -> 45912.426 | G10: 3.973
A11: =A10 -> PROLOR | B11: =IF(ISBLANK(A8),"",LEFT(B10,27)&VALUE(RIGHT(B10,1)+1)) -> DKF250911PROLOR_20C_sample_4 | C11: =C10 -> Protea lorifolia | D11: =D10 -> 20C | E11: =IF(ISBLANK(A8),"",E10+1) -> 4 | F11: =F10 -> 45912.426 | G11: 3.16
A12: =A11 -> PROLOR | B12: =IF(ISBLANK(A8),"",LEFT(B11,27)&VALUE(RIGHT(B11,1)+1)) -> DKF250911PROLOR_20C_sample_5 | C12: =C11 -> Protea lorifolia | D12: =D11 -> 20C | E12: =IF(ISBLANK(A8),"",E11+1) -> 5 | F12: =F11 -> 45912.426 | G12: 5.853
A13: =A12 -> PROLOR | B13: =IF(ISBLANK(A8),"",LEFT(B12,27)&VALUE(RIGHT(B12,1)+1)) -> DKF250911PROLOR_20C_sample_6 | C13: =C12 -> Protea lorifolia | D13: =D12 -> 20C | E13: =IF(ISBLANK(A8),"",E12+1) -> 6 | F13: =F12 -> 45912.426 | G13: 4.8
A14: PROLAU | B14: =IF(ISBLANK(A14),"",VLOOKUP($A14,'Data Feed (20C)'!$A$1:$G$14,2,FALSE)) -> DKR250911PROLAU_20C_sample_1 | C14: =IF(ISBLANK(A14),"",VLOOKUP($A14,'Data Feed (20C)'!$A$1:$G$14,3,FALSE)) -> Protea laurifolia | D14: =IF(ISBLANK(A14),"",VLOOKUP($A14,'Data Feed (20C)'!$A$1:$G$14,4,FALSE)) -> 20C | E14: =IF(ISBLANK(A14),"",VLOOKUP($A14,'Data Feed (20C)'!$A$1:$G$14,7,FALSE)) -> 1 | F14: 45912.433 | G14: 1.077
A15: =A14 -> PROLAU | B15: =IF(ISBLANK(A14),"",LEFT(B14,27)&VALUE(RIGHT(B14,1)+1)) -> DKR250911PROLAU_20C_sample_2 | C15: =C14 -> Protea laurifolia | D15: =D14 -> 20C | E15: =IF(ISBLANK(A14),"",E14+1) -> 2 | F15: =F14 -> 45912.433 | G15: 1.315
A16: =A15 -> PROLAU | B16: =IF(ISBLANK(A14),"",LEFT(B15,27)&VALUE(RIGHT(B15,1)+1)) -> DKR250911PROLAU_20C_sample_3 | C16: =C15 -> Protea laurifolia | D16: =D15 -> 20C | E16: =IF(ISBLANK(A14),"",E15+1) -> 3 | F16: =F15 -> 45912.433 | G16: 1.185
A17: =A16 -> PROLAU | B17: =IF(ISBLANK(A14),"",LEFT(B16,27)&VALUE(RIGHT(B16,1)+1)) -> DKR250911PROLAU_20C_sample_4 | C17: =C16 -> Protea laurifolia | D17: =D16 -> 20C | E17: =IF(ISBLANK(A14),"",E16+1) -> 4 | F17: =F16 -> 45912.433 | G17: 0.591
A18: =A17 -> PROLAU | B18: =IF(ISBLANK(A14),"",LEFT(B17,27)&VALUE(RIGHT(B17,1)+1)) -> DKR250911PROLAU_20C_sample_5 | C18: =C17 -> Protea laurifolia | D18: =D17 -> 20C | E18: =IF(ISBLANK(A14),"",E17+1) -> 5 | F18: =F17 -> 45912.433 | G18: 1.035
A19: =A18 -> PROLAU | B19: =IF(ISBLANK(A14),"",LEFT(B18,27)&VALUE(RIGHT(B18,1)+1)) -> DKR250911PROLAU_20C_sample_6 | C19: =C18 -> Protea laurifolia | D19: =D18 -> 20C | E19: =IF(ISBLANK(A14),"",E18+1) -> 6 | F19: =F18 -> 45912.433 | G19: 1.048
A20: LOBDEC | B20: =IF(ISBLANK(A20),"",VLOOKUP($A20,'Data Feed (20C)'!$A$1:$G$14,2,FALSE)) -> DKF250911LOBDEC_20C_sample_1 | C20: =IF(ISBLANK(A20),"",VLOOKUP($A20,'Data Feed (20C)'!$A$1:$G$14,3,FALSE)) -> Lobostemon decorus | D20: =IF(ISBLANK(A20),"",VLOOKUP($A20,'Data Feed (20C)'!$A$1:$G$14,4,FALSE)) -> 20C | E20: =IF(ISBLANK(A20),"",VLOOKUP($A20,'Data Feed (20C)'!$A$1:$G$14,7,FALSE)) -> 1 | F20: 45912.435 | G20: 13.153
A21: =A20 -> LOBDEC | B21: =IF(ISBLANK(A20),"",LEFT(B20,27)&VALUE(RIGHT(B20,1)+1)) -> DKF250911LOBDEC_20C_sample_2 | C21: =C20 -> Lobostemon decorus | D21: =D20 -> 20C | E21: =IF(ISBLANK(A20),"",E20+1) -> 2 | F21: =F20 -> 45912.435 | G21: 10.143
A22: =A21 -> LOBDEC | B22: =IF(ISBLANK(A20),"",LEFT(B21,27)&VALUE(RIGHT(B21,1)+1)) -> DKF250911LOBDEC_20C_sample_3 | C22: =C21 -> Lobostemon decorus | D22: =D21 -> 20C | E22: =IF(ISBLANK(A20),"",E21+1) -> 3 | F22: =F21 -> 45912.435 | G22: 12.837
A23: =A22 -> LOBDEC | B23: =IF(ISBLANK(A20),"",LEFT(B22,27)&VALUE(RIGHT(B22,1)+1)) -> DKF250911LOBDEC_20C_sample_4 | C23: =C22 -> Lobostemon decorus | D23: =D22 -> 20C | E23: =IF(ISBLANK(A20),"",E22+1) -> 4 | F23: =F22 -> 45912.435 | G23: 9.209
A24: =A23 -> LOBDEC | B24: =IF(ISBLANK(A20),"",LEFT(B23,27)&VALUE(RIGHT(B23,1)+1)) -> DKF250911LOBDEC_20C_sample_5 | C24: =C23 -> Lobostemon decorus | D24: =D23 -> 20C | E24: =IF(ISBLANK(A20),"",E23+1) -> 5 | F24: =F23 -> 45912.435 | G24: 6.164
A25: =A24 -> LOBDEC | B25: =IF(ISBLANK(A20),"",LEFT(B24,27)&VALUE(RIGHT(B24,1)+1)) -> DKF250911LOBDEC_20C_sample_6 | C25: =C24 -> Lobostemon decorus | D25: =D24 -> 20C | E25: =IF(ISBLANK(A20),"",E24+1) -> 6 | F25: =F24 -> 45912.435 | G25: 6.343
A26: SELDOL | B26: =IF(ISBLANK(A26),"",VLOOKUP($A26,'Data Feed (20C)'!$A$1:$G$14,2,FALSE)) -> DKF250911SELDOL_20C_sample_1 | C26: =IF(ISBLANK(A26),"",VLOOKUP($A26,'Data Feed (20C)'!$A$1:$G$14,3,FALSE)) -> Selago dolosa | D26: =IF(ISBLANK(A26),"",VLOOKUP($A26,'Data Feed (20C)'!$A$1:$G$14,4,FALSE)) -> 20C | E26: =IF(ISBLANK(A26),"",VLOOKUP($A26,'Data Feed (20C)'!$A$1:$G$14,7,FALSE)) -> 1 | F26: 45912.438 | G26: 1.75
A27: =A26 -> SELDOL | B27: =IF(ISBLANK(A26),"",LEFT(B26,27)&VALUE(RIGHT(B26,1)+1)) -> DKF250911SELDOL_20C_sample_2 | C27: =C26 -> Selago dolosa | D27: =D26 -> 20C | E27: =IF(ISBLANK(A26),"",E26+1) -> 2 | F27: =F26 -> 45912.438 | G27: 2.323
A28: =A27 -> SELDOL | B28: =IF(ISBLANK(A26),"",LEFT(B27,27)&VALUE(RIGHT(B27,1)+1)) -> DKF250911SELDOL_20C_sample_3 | C28: =C27 -> Selago dolosa | D28: =D27 -> 20C | E28: =IF(ISBLANK(A26),"",E27+1) -> 3 | F28: =F27 -> 45912.438 | G28: 2.27
A29: =A28 -> SELDOL | B29: =IF(ISBLANK(A26),"",LEFT(B28,27)&VALUE(RIGHT(B28,1)+1)) -> DKF250911SELDOL_20C_sample_4 | C29: =C28 -> Selago dolosa | D29: =D28 -> 20C | E29: =IF(ISBLANK(A26),"",E28+1) -> 4 | F29: =F28 -> 45912.438 | G29: 2.39
A30: =A29 -> SELDOL | B30: =IF(ISBLANK(A26),"",LEFT(B29,27)&VALUE(RIGHT(B29,1)+1)) -> DKF250911SELDOL_20C_sample_5 | C30: =C29 -> Selago dolosa | D30: =D29 -> 20C | E30: =IF(ISBLANK(A26),"",E29+1) -> 5 | F30: =F29 -> 45912.438 | G30: 3.188
A31: =A30 -> SELDOL | B31: =IF(ISBLANK(A26),"",LEFT(B30,27)&VALUE(RIGHT(B30,1)+1)) -> DKF250911SELDOL_20C_sample_6 | C31: =C30 -> Selago dolosa | D31: =D30 -> 20C | E31: =IF(ISBLANK(A26),"",E30+1) -> 6 | F31: =F30 -> 45912.438 | G31: 1.451
A32: AGACAP | B32: =IF(ISBLANK(A32),"",VLOOKUP($A32,'Data Feed (20C)'!$A$1:$G$14,2,FALSE)) -> DKF250911AGACAP_20C_sample_1 | C32: =IF(ISBLANK(A32),"",VLOOKUP($A32,'Data Feed (20C)'!$A$1:$G$14,3,FALSE)) -> Agathosma capensis | D32: =IF(ISBLANK(A32),"",VLOOKUP($A32,'Data Feed (20C)'!$A$1:$G$14,4,FALSE)) -> 20C | E32: =IF(ISBLANK(A32),"",VLOOKUP($A32,'Data Feed (20C)'!$A$1:$G$14,7,FALSE)) -> 1 | F32: 45912.447 | G32: 5.789
A33: =A32 -> AGACAP | B33: =IF(ISBLANK(A32),"",LEFT(B32,27)&VALUE(RIGHT(B32,1)+1)) -> DKF250911AGACAP_20C_sample_2 | C33: =C32 -> Agathosma capensis | D33: =D32 -> 20C | E33: =IF(ISBLANK(A32),"",E32+1) -> 2 | F33: =F32 -> 45912.447 | G33: 2.065
A34: =A33 -> AGACAP | B34: =IF(ISBLANK(A32),"",LEFT(B33,27)&VALUE(RIGHT(B33,1)+1)) -> DKF250911AGACAP_20C_sample_3 | C34: =C33 -> Agathosma capensis | D34: =D33 -> 20C | E34: =IF(ISBLANK(A32),"",E33+1) -> 3 | F34: =F33 -> 45912.447 | G34: 3.022
A35: =A34 -> AGACAP | B35: =IF(ISBLANK(A32),"",LEFT(B34,27)&VALUE(RIGHT(B34,1)+1)) -> DKF250911AGACAP_20C_sample_4 | C35: =C34 -> Agathosma capensis | D35: =D34 -> 20C | E35: =IF(ISBLANK(A32),"",E34+1) -> 4 | F35: =F34 -> 45912.447 | G35: 1.965
A36: =A35 -> AGACAP | B36: =IF(ISBLANK(A32),"",LEFT(B35,27)&VALUE(RIGHT(B35,1)+1)) -> DKF250911AGACAP_20C_sample_5 | C36: =C35 -> Agathosma capensis | D36: =D35 -> 20C | E36: =IF(ISBLANK(A32),"",E35+1) -> 5 | F36: =F35 -> 45912.447 | G36: 0.829
A37: =A36 -> AGACAP | B37: =IF(ISBLANK(A32),"",LEFT(B36,27)&VALUE(RIGHT(B36,1)+1)) -> DKF250911AGACAP_20C_sample_6 | C37: =C36 -> Agathosma capensis | D37: =D36 -> 20C | E37: =IF(ISBLANK(A32),"",E36+1) -> 6 | F37: =F36 -> 45912.447 | G37: 2.157
A38: RUSMUL | B38: =IF(ISBLANK(A38),"",VLOOKUP($A38,'Data Feed (20C)'!$A$1:$G$14,2,FALSE)) -> DKR250911RUSMUL_20C_sample_1 | C38: =IF(ISBLANK(A38),"",VLOOKUP($A38,'Data Feed (20C)'!$A$1:$G$14,3,FALSE)) -> Ruschia multiflora | D38: =IF(ISBLANK(A38),"",VLOOKUP($A38,'Data Feed (20C)'!$A$1:$G$14,4,FALSE)) -> 20C | E38: =IF(ISBLANK(A38),"",VLOOKUP($A38,'Data Feed (20C)'!$A$1:$G$14,7,FALSE)) -> 1 | F38: 45912.453 | G38: 3.48
A39: =A38 -> RUSMUL | B39: =IF(ISBLANK(A38),"",LEFT(B38,27)&VALUE(RIGHT(B38,1)+1)) -> DKR250911RUSMUL_20C_sample_2 | C39: =C38 -> Ruschia multiflora | D39: =D38 -> 20C | E39: =IF(ISBLANK(A38),"",E38+1) -> 2 | F39: =F38 -> 45912.453 | G39: 4.591
A40: =A39 -> RUSMUL | B40: =IF(ISBLANK(A38),"",LEFT(B39,27)&VALUE(RIGHT(B39,1)+1)) -> DKR250911RUSMUL_20C_sample_3 | C40: =C39 -> Ruschia multiflora | D40: =D39 -> 20C | E40: =IF(ISBLANK(A38),"",E39+1) -> 3 | F40: =F39 -> 45912.453 | G40: 8.479
...

Sheet Data Feed (40C)
A1: GENSPP | B1: ID_Code | C1: Species | D1: Treat | E1: Site | F1: Sampling Date | G1: Sample No.
A2: =UPPER(LEFT(C2,3) & MID(C2,FIND(" ",C2)+1,3)) -> AGACAP | B2: =CONCATENATE("DK", UPPER(LEFT(E2,1)), "25", UPPER(TEXT(F2,"mm")), UPPER(TEXT(F2,"dd")), UPPER(LEFT(C2,3)), UPPER(MID(C2,FIND(" ",C2)+1,3)),"_",D2,"_sample_",G2) -> DKF250911AGACAP_20C_sample_1 | C2: Agathosma capensis | D2: 20C | E2: Fynbos | F2: 45911 | G2: 1
A3: =UPPER(LEFT(C3,3) & MID(C3,FIND(" ",C3)+1,3)) -> ASPSHA | B3: =CONCATENATE("DK", UPPER(LEFT(E3,1)), "25", UPPER(TEXT(F3,"mm")), UPPER(TEXT(F3,"dd")), UPPER(LEFT(C3,3)), UPPER(MID(C3,FIND(" ",C3)+1,3)),"_",D3,"_sample_",G3) -> DKF250911ASPSHA_20C_sample_1 | C3: Aspalathus shawii | D3: 20C | E3: Fynbos | F3: 45911 | G3: 1
A4: =UPPER(LEFT(C4,3) & MID(C4,FIND(" ",C4)+1,3)) -> CLURUB | B4: =CONCATENATE("DK", UPPER(LEFT(E4,1)), "25", UPPER(TEXT(F4,"mm")), UPPER(TEXT(F4,"dd")), UPPER(LEFT(C4,3)), UPPER(MID(C4,FIND(" ",C4)+1,3)),"_",D4,"_sample_",G4) -> DKR250911CLURUB_20C_sample_1 | C4: Clutia rubricaulis | D4: 20C | E4: Renosterveld | F4: 45911 | G4: 1
A5: =UPPER(LEFT(C5,3) & MID(C5,FIND(" ",C5)+1,3)) -> ELYRHI | B5: =CONCATENATE("DK", UPPER(LEFT(E5,1)), "25", UPPER(TEXT(F5,"mm")), UPPER(TEXT(F5,"dd")), UPPER(LEFT(C5,3)), UPPER(MID(C5,FIND(" ",C5)+1,3)),"_",D5,"_sample_",G5) -> DKR250911ELYRHI_20C_sample_1 | C5: Elytropappus rhinocerotis | D5: 20C | E5: Renosterveld | F5: 45911 | G5: 1
A6: =UPPER(LEFT(C6,3) & MID(C6,FIND(" ",C6)+1,3)) -> LOBDEC | B6: =CONCATENATE("DK", UPPER(LEFT(E6,1)), "25", UPPER(TEXT(F6,"mm")), UPPER(TEXT(F6,"dd")), UPPER(LEFT(C6,3)), UPPER(MID(C6,FIND(" ",C6)+1,3)),"_",D6,"_sample_",G6) -> DKF250911LOBDEC_20C_sample_1 | C6: Lobostemon decorus | D6: 20C | E6: Fynbos | F6: 45911 | G6: 1
A7: =UPPER(LEFT(C7,3) & MID(C7,FIND(" ",C7)+1,3)) -> MICPOL | B7: =CONCATENATE("DK", UPPER(LEFT(E7,1)), "25", UPPER(TEXT(F7,"mm")), UPPER(TEXT(F7,"dd")), UPPER(LEFT(C7,3)), UPPER(MID(C7,FIND(" ",C7)+1,3)),"_",D7,"_sample_",G7) -> DKR250911MICPOL_20C_sample_1 | C7: Microdon polygaloides | D7: 20C | E7: Renosterveld | F7: 45911 | G7: 1
A8: =UPPER(LEFT(C8,3) & MID(C8,FIND(" ",C8)+1,3)) -> OEDSQU | B8: =CONCATENATE("DK", UPPER(LEFT(E8,1)), "25", UPPER(TEXT(F8,"mm")), UPPER(TEXT(F8,"dd")), UPPER(LEFT(C8,3)), UPPER(MID(C8,FIND(" ",C8)+1,3)),"_",D8,"_sample_",G8) -> DKR250911OEDSQU_20C_sample_1 | C8: Oedera squarrosa | D8: 20C | E8: Renosterveld | F8: 45911 | G8: 1
A9: =UPPER(LEFT(C9,3) & MID(C9,FIND(" ",C9)+1,3)) -> PASOBT | B9: =CONCATENATE("DK", UPPER(LEFT(E9,1)), "25", UPPER(TEXT(F9,"mm")), UPPER(TEXT(F9,"dd")), UPPER(LEFT(C9,3)), UPPER(MID(C9,FIND(" ",C9)+1,3)),"_",D9,"_sample_",G9) -> DKR250911PASOBT_20C_sample_1 | C9: Passerina obtusifolia | D9: 20C | E9: Renosterveld | F9: 45911 | G9: 1
A10: =UPPER(LEFT(C10,3) & MID(C10,FIND(" ",C10)+1,3)) -> PROLAU | B10: =CONCATENATE("DK", UPPER(LEFT(E10,1)), "25", UPPER(TEXT(F10,"mm")), UPPER(TEXT(F10,"dd")), UPPER(LEFT(C10,3)), UPPER(MID(C10,FIND(" ",C10)+1,3)),"_",D10,"_sample_",G10) -> DKR250911PROLAU_20C_sample_1 | C10: Protea laurifolia | D10: 20C | E10: Renosterveld | F10: 45911 | G10: 1
A11: =UPPER(LEFT(C11,3) & MID(C11,FIND(" ",C11)+1,3)) -> PROLOR | B11: =CONCATENATE("DK", UPPER(LEFT(E11,1)), "25", UPPER(TEXT(F11,"mm")), UPPER(TEXT(F11,"dd")), UPPER(LEFT(C11,3)), UPPER(MID(C11,FIND(" ",C11)+1,3)),"_",D11,"_sample_",G11) -> DKF250911PROLOR_20C_sample_1 | C11: Protea lorifolia | D11: 20C | E11: Fynbos | F11: 45911 | G11: 1
A12: =UPPER(LEFT(C12,3) & MID(C12,FIND(" ",C12)+1,3)) -> RUSMUL | B12: =CONCATENATE("DK", UPPER(LEFT(E12,1)), "25", UPPER(TEXT(F12,"mm")), UPPER(TEXT(F12,"dd")), UPPER(LEFT(C12,3)), UPPER(MID(C12,FIND(" ",C12)+1,3)),"_",D12,"_sample_",G12) -> DKR250911RUSMUL_20C_sample_1 | C12: Ruschia multiflora | D12: 20C | E12: Renosterveld | F12: 45911 | G12: 1
A13: =UPPER(LEFT(C13,3) & MID(C13,FIND(" ",C13)+1,3)) -> SELDOL | B13: =CONCATENATE("DK", UPPER(LEFT(E13,1)), "25", UPPER(TEXT(F13,"mm")), UPPER(TEXT(F13,"dd")), UPPER(LEFT(C13,3)), UPPER(MID(C13,FIND(" ",C13)+1,3)),"_",D13,"_sample_",G13) -> DKF250911SELDOL_20C_sample_1 | C13: Selago dolosa | D13: 20C | E13: Fynbos | F13: 45911 | G13: 1
A14: =UPPER(LEFT(C14,3) & MID(C14,FIND(" ",C14)+1,3)) -> WAHNOD | B14: =CONCATENATE("DK", UPPER(LEFT(E14,1)), "25", UPPER(TEXT(F14,"mm")), UPPER(TEXT(F14,"dd")), UPPER(LEFT(C14,3)), UPPER(MID(C14,FIND(" ",C14)+1,3)),"_",D14,"_sample_",G14) -> DKR250911WAHNOD_20C_sample_1 | C14: Wahlenbergia nodosa | D14: 20C | E14: Renosterveld | F14: 45911 | G14: 1

Sheet Data Feed (20C)
A1: GENSPP | B1: ID_Code | C1: Species | D1: Treat | E1: Site | F1: Sampling Date | G1: Sample No.
A2: =UPPER(LEFT(C2,3) & MID(C2,FIND(" ",C2)+1,3)) -> AGACAP | B2: =CONCATENATE("DK", UPPER(LEFT(E2,1)), "25", UPPER(TEXT(F2,"mm")), UPPER(TEXT(F2,"dd")), UPPER(LEFT(C2,3)), UPPER(MID(C2,FIND(" ",C2)+1,3)),"_",D2,"_sample_",G2) -> DKF250911AGACAP_20C_sample_1 | C2: Agathosma capensis | D2: 20C | E2: Fynbos | F2: 45911 | G2: 1
A3: =UPPER(LEFT(C3,3) & MID(C3,FIND(" ",C3)+1,3)) -> ASPSHA | B3: =CONCATENATE("DK", UPPER(LEFT(E3,1)), "25", UPPER(TEXT(F3,"mm")), UPPER(TEXT(F3,"dd")), UPPER(LEFT(C3,3)), UPPER(MID(C3,FIND(" ",C3)+1,3)),"_",D3,"_sample_",G3) -> DKF250911ASPSHA_20C_sample_1 | C3: Aspalathus shawii | D3: 20C | E3: Fynbos | F3: 45911 | G3: 1
A4: =UPPER(LEFT(C4,3) & MID(C4,FIND(" ",C4)+1,3)) -> CLURUB | B4: =CONCATENATE("DK", UPPER(LEFT(E4,1)), "25", UPPER(TEXT(F4,"mm")), UPPER(TEXT(F4,"dd")), UPPER(LEFT(C4,3)), UPPER(MID(C4,FIND(" ",C4)+1,3)),"_",D4,"_sample_",G4) -> DKR250911CLURUB_20C_sample_1 | C4: Clutia rubricaulis | D4: 20C | E4: Renosterveld | F4: 45911 | G4: 1
A5: =UPPER(LEFT(C5,3) & MID(C5,FIND(" ",C5)+1,3)) -> ELYRHI | B5: =CONCATENATE("DK", UPPER(LEFT(E5,1)), "25", UPPER(TEXT(F5,"mm")), UPPER(TEXT(F5,"dd")), UPPER(LEFT(C5,3)), UPPER(MID(C5,FIND(" ",C5)+1,3)),"_",D5,"_sample_",G5) -> DKR250911ELYRHI_20C_sample_1 | C5: Elytropappus rhinocerotis | D5: 20C | E5: Renosterveld | F5: 45911 | G5: 1
A6: =UPPER(LEFT(C6,3) & MID(C6,FIND(" ",C6)+1,3)) -> LOBDEC | B6: =CONCATENATE("DK", UPPER(LEFT(E6,1)), "25", UPPER(TEXT(F6,"mm")), UPPER(TEXT(F6,"dd")), UPPER(LEFT(C6,3)), UPPER(MID(C6,FIND(" ",C6)+1,3)),"_",D6,"_sample_",G6) -> DKF250911LOBDEC_20C_sample_1 | C6: Lobostemon decorus | D6: 20C | E6: Fynbos | F6: 45911 | G6: 1
A7: =UPPER(LEFT(C7,3) & MID(C7,FIND(" ",C7)+1,3)) -> MICPOL | B7: =CONCATENATE("DK", UPPER(LEFT(E7,1)), "25", UPPER(TEXT(F7,"mm")), UPPER(TEXT(F7,"dd")), UPPER(LEFT(C7,3)), UPPER(MID(C7,FIND(" ",C7)+1,3)),"_",D7,"_sample_",G7) -> DKR250911MICPOL_20C_sample_1 | C7: Microdon polygaloides | D7: 20C | E7: Renosterveld | F7: 45911 | G7: 1
A8: =UPPER(LEFT(C8,3) & MID(C8,FIND(" ",C8)+1,3)) -> OEDSQU | B8: =CONCATENATE("DK", UPPER(LEFT(E8,1)), "25", UPPER(TEXT(F8,"mm")), UPPER(TEXT(F8,"dd")), UPPER(LEFT(C8,3)), UPPER(MID(C8,FIND(" ",C8)+1,3)),"_",D8,"_sample_",G8) -> DKR250911OEDSQU_20C_sample_1 | C8: Oedera squarrosa | D8: 20C | E8: Renosterveld | F8: 45911 | G8: 1
A9: =UPPER(LEFT(C9,3) & MID(C9,FIND(" ",C9)+1,3)) -> PASOBT | B9: =CONCATENATE("DK", UPPER(LEFT(E9,1)), "25", UPPER(TEXT(F9,"mm")), UPPER(TEXT(F9,"dd")), UPPER(LEFT(C9,3)), UPPER(MID(C9,FIND(" ",C9)+1,3)),"_",D9,"_sample_",G9) -> DKR250911PASOBT_20C_sample_1 | C9: Passerina obtusifolia | D9: 20C | E9: Renosterveld | F9: 45911 | G9: 1
A10: =UPPER(LEFT(C10,3) & MID(C10,FIND(" ",C10)+1,3)) -> PROLAU | B10: =CONCATENATE("DK", UPPER(LEFT(E10,1)), "25", UPPER(TEXT(F10,"mm")), UPPER(TEXT(F10,"dd")), UPPER(LEFT(C10,3)), UPPER(MID(C10,FIND(" ",C10)+1,3)),"_",D10,"_sample_",G10) -> DKR250911PROLAU_20C_sample_1 | C10: Protea laurifolia | D10: 20C | E10: Renosterveld | F10: 45911 | G10: 1
A11: =UPPER(LEFT(C11,3) & MID(C11,FIND(" ",C11)+1,3)) -> PROLOR | B11: =CONCATENATE("DK", UPPER(LEFT(E11,1)), "25", UPPER(TEXT(F11,"mm")), UPPER(TEXT(F11,"dd")), UPPER(LEFT(C11,3)), UPPER(MID(C11,FIND(" ",C11)+1,3)),"_",D11,"_sample_",G11) -> DKF250911PROLOR_20C_sample_1 | C11: Protea lorifolia | D11: 20C | E11: Fynbos | F11: 45911 | G11: 1
A12: =UPPER(LEFT(C12,3) & MID(C12,FIND(" ",C12)+1,3)) -> RUSMUL | B12: =CONCATENATE("DK", UPPER(LEFT(E12,1)), "25", UPPER(TEXT(F12,"mm")), UPPER(TEXT(F12,"dd")), UPPER(LEFT(C12,3)), UPPER(MID(C12,FIND(" ",C12)+1,3)),"_",D12,"_sample_",G12) -> DKR250911RUSMUL_20C_sample_1 | C12: Ruschia multiflora | D12: 20C | E12: Renosterveld | F12: 45911 | G12: 1
A13: =UPPER(LEFT(C13,3) & MID(C13,FIND(" ",C13)+1,3)) -> SELDOL | B13: =CONCATENATE("DK", UPPER(LEFT(E13,1)), "25", UPPER(TEXT(F13,"mm")), UPPER(TEXT(F13,"dd")), UPPER(LEFT(C13,3)), UPPER(MID(C13,FIND(" ",C13)+1,3)),"_",D13,"_sample_",G13) -> DKF250911SELDOL_20C_sample_1 | C13: Selago dolosa | D13: 20C | E13: Fynbos | F13: 45911 | G13: 1
A14: =UPPER(LEFT(C14,3) & MID(C14,FIND(" ",C14)+1,3)) -> WAHNOD | B14: =CONCATENATE("DK", UPPER(LEFT(E14,1)), "25", UPPER(TEXT(F14,"mm")), UPPER(TEXT(F14,"dd")), UPPER(LEFT(C14,3)), UPPER(MID(C14,FIND(" ",C14)+1,3)),"_",D14,"_sample_",G14) -> DKR250911WAHNOD_20C_sample_1 | C14: Wahlenbergia nodosa | D14: 20C | E14: Renosterveld | F14: 45911 | G14: 1
